File: M16M3-MH10.csv
Magnetic Field (Oe),Temperature (K),Moment (emu),M (emu/g)
0.3931894749403,10.0049686,1.35316020412594E-5,4.73132938505573E-4
985.467041015625,10.004777,0.0202667129530831,0.708626327030878
1597.66015625,10.0034432,0.0359525682686269,1.25708280659535
2382.18798828125,10.0029392,0.0516714925334154,1.80669554312641
2949.75732421875,10.00285385,0.0649284411303882,2.27022521434924
3695.78625488281,10.0025339,0.0805923278348657,2.81791356065964
4321.27221679687,10.001585,0.0961424234569497,3.36162319779544
5291.56494140625,10.0015378,0.118211229290963,4.13325976541829
6031.896484375,10.00143335,0.133505101506458,4.66801054218385
6626.8720703125,10.00165555,0.146489877602024,5.12202369237846
7346.8740234375,10.0010233,0.16153627310738,5.64812143732098
8036.82666015625,10.00150345,0.176412522701283,6.16827002452038
8651.75341796875,10.00076195,0.18903393019492,6.60957797884336
9322.48046875,10.00098845,0.20359628145516,7.11875109983077
9956.94677734375,10.000813,0.21592951883906,7.54998317619091
10647.4946289062,10.00055125,0.230141766719629,8.04691492026675
11382.3408203125,10.0001812,0.244129454032249,8.53599489623248
12157.095703125,10.00080015,0.259867612475066,9.08628015647084
12736.798828125,10.00020695,0.271495968148948,9.49286601919399
13362.0512695313,10.00057745,0.284834435536022,9.95924599776301
13982.2412109375,9.99974585,0.29610039988811,10.3531608352486
14821.869140625,10.000411,0.310832117545582,10.8682558582371
15376.92578125,9.99949645,0.321694695782876,11.2480662861145
16087.4970703125,9.99972725,0.334113457091909,11.6822887095073
16743.1953125,9.99981545,0.344622749563743,12.0497464882428
17378.7421875,10.00004675,0.356593436608187,12.4683019793072
18124.5029296875,9.99972395,0.36833111878651,12.8787104470808
18844.9794921875,9.99877595,0.379814645209628,13.280232349987
19425.546875,9.99963615,0.389487484726998,13.618443521923
20121.0234375,9.9994979,0.400542961190489,14.0049986430241
20856.7763671875,9.9990368,0.411324049192425,14.3819597619729
21552.5712890625,9.99901105,0.421892188345214,14.7514751169655
22133.3056640625,9.99927425,0.430753397681659,15.0613076112468
22873.794921875,9.9987402,0.440844372296028,15.4141388914695
23534.54296875,9.9987087,0.450719428070377,15.7594205619013
24145.021484375,9.99902155,0.458976613671429,16.0481333451549
24740.8037109375,9.99913075,0.46705995333105,16.3307675989878
25396.2353515625,9.999331,0.476330490779273,16.6549122650096
26052.28515625,9.99883125,0.484048091453375,16.9247584424257
26812.880859375,9.99926995,0.494149931670726,17.2779696388366
27463.58984375,9.99897335,0.50148479488535,17.5344333875996
28254.283203125,9.9988575,0.511083667879531,17.8700583174661
28844.837890625,9.99811025,0.51811973713338,18.1160747249434
29465.3232421875,9.99882315,0.524944073937419,18.3546878999098
30176.23046875,9.99832775,0.533862842088336,18.6665329401516
30762.0771484375,9.9983902,0.539303816272807,18.8567767927555
31467.7314453125,9.998312,0.546734753974782,19.116599789328
32118.2841796875,9.99847175,0.554037014871517,19.3719235969062
32723.888671875,9.9985857,0.560130857417486,19.5849950145974
33354.447265625,9.9985156,0.566070348490503,19.79266952764
34059.93359375,9.9981546,0.572848859946341,20.0296804177042
34750.375,9.997777,0.579500320341446,20.2622489629876
35336.32421875,9.99803735,0.585037454153738,20.4558550403405
36106.955078125,9.9983625,0.591349889900135,20.6765695769278
36737.6484375,9.99751235,0.597522428748129,20.8923926135709
37433.12109375,9.9978971,0.603576602607442,21.1040770142462
38068.748046875,9.9976101,0.608564534878211,21.2784802404969
38759.525390625,9.99746755,0.614378989142142,21.4817828371378
39480.291015625,9.9976244,0.619917199886528,21.675426569459
40200.861328125,9.9983654,0.625404054200535,21.8672746223963
40896.279296875,9.9985981,0.630761301500602,22.0545909615595
41472.005859375,9.9979129,0.635249927429688,22.211535924115
42137.634765625,9.99774645,0.640344625492907,22.3896722200317
42863.171875,9.9974985,0.645360877525627,22.5650656477492
43524.26171875,9.9980268,0.649560548158311,22.7119072782626
44255.177734375,9.997735,0.65502650187595,22.9030245411171
44835.453125,9.99780225,0.659008690816634,23.0422619166655
45576.224609375,9.9978952,0.663574499808621,23.201905587714
46221.677734375,9.998517,0.667441403578009,23.3371120132171
46922.44140625,9.99768685,0.672413219323325,23.5109517245918
47573.603515625,9.9981494,0.676074557542728,23.638970543452
48299.2734375,9.9979429,0.68021632080918,23.7837874408804
49024.744140625,9.9981642,0.684334813886147,23.9277906953198
49680.17578125,9.9983177,0.688377927942908,24.0691583196821
50400.734375,9.99822665,0.692265508552728,24.2050877116338
50996.443359375,9.9985027,0.696084262469584,24.3386105758596
51687.158203125,9.9986496,0.699803790323281,24.4686639973175
52392.810546875,9.99808215,0.703554599049864,24.5998111555896
53088.509765625,9.9977474,0.707150314023176,24.7255354553558
53728.654296875,9.99818465,0.710160552030146,24.8307885325226
54369.419921875,9.99753285,0.713128816215515,24.9345739935495
54980.17578125,9.997828,0.71606075434445,25.037089312743
55605.5390625,9.9975419,0.719391192619061,25.1535382034637
56306.06640625,9.9982843,0.722669751445351,25.2681731274598
57042.26171875,9.9976873,0.725879980479096,25.3804188978705
57677.5859375,9.9984145,0.728515487513507,25.4725694934793
58408.478515625,9.99827285,0.731673832871516,25.5830011493537
58988.8125,9.9978685,0.734707723050245,25.689081225533
59704.39453125,9.9988232,0.73723442324278,25.7774273861112
60295.048828125,9.99834825,0.740255778688367,25.8830691849079
60955.91796875,9.9976249,0.742754084948082,25.9704225506322
61661.595703125,9.9978857,0.745527835102144,26.0674068217533
62312.65625,9.9981909,0.748372166275726,26.1668589606897
63010.994140625,9.9983273,0.750699743993492,26.2482427969753
63594.248046875,9.9970527,0.753025150993503,26.3295507340386
64212.609375,9.9983926,0.755659362882993,26.4216560448599
64870.888671875,9.9980693,0.757985818055403,26.5030006313078
65514.578125,9.9984698,0.760500500057788,26.5909265754471
66163.4140625,9.9986377,0.762678881089665,26.6670937443939
66917.40234375,9.9981394,0.765154270219039,26.7536458118545
67580.38671875,9.9982738,0.767585585649891,26.8386568409053
68259.31640625,9.9979677,0.769753965058769,26.9144743027542
68822.28125,9.99816465,0.772095849934639,26.996358389323
69485.8984375,9.9984584,0.774133392301113,27.0676011294095
70289.94140625,9.9977303,0.776731869522255,27.1584569763026
70953.609375,9.99767925,0.778653679519586,27.2256531300555
71572.0625,9.99848505,0.780925819332435,27.3050985780572
72235.2734375,9.9975486,0.782832829589444,27.3717772583722
72853.55078125,9.9980936,0.784971413062952,27.446552904299
73466.87109375,9.99802825,0.786840646388215,27.5119107128746
74181.20703125,9.9984617,0.788624999717713,27.5743006894305
74784.28515625,9.99826525,0.79069393091611,27.6466409411227
75447.703125,9.99731685,0.792465031988135,27.7085675520327
76181.4921875,9.9980946,0.794508258979254,27.7800090552187
76915.1953125,9.9983492,0.796747394260474,27.858300498618
77483.3046875,9.99720525,0.798463006648984,27.9182869457687
78308.203125,9.9972162,0.800380695253184,27.9853389948666
78926.83203125,9.99799965,0.802276065252715,28.0516106731718
79620.171875,9.9973736,0.803888957407863,28.1080055037714
80338.94140625,9.9978256,0.806025447950177,28.1827079702859
80967.40625,9.997427,0.807557985019308,28.2362931824933
81736.4140625,9.9980431,0.809618246579831,28.3083302999941
82309.60546875,9.99733305,0.811126800757723,28.3610769495707
82988.34765625,9.99689055,0.812678460297361,28.415330779628
83772.52734375,9.99712565,0.814645221857391,28.4840986663423
84531.75390625,9.9975939,0.816378300789928,28.5446958318157
85119.6328125,9.99714805,0.818063523360215,28.6036196979096
85853.5625,9.9964151,0.819711762082219,28.6612504224552
86512.171875,9.99704935,0.821387840281228,28.7198545552877
87160.44921875,9.996634,0.822826904076693,28.770171471213
87809.04296875,9.99669265,0.824127562609031,28.8156490422738
88502.60546875,9.99704265,0.825747913583576,28.8723046707544
89140.95703125,9.9970231,0.827339802021177,28.9279651056356
89884.78515625,9.997057,0.828877255939305,28.98172223564
89631.85546875,9.9975195,0.828674709248107,28.9746401835002
88949.53125,9.996974,0.827065233227912,28.9183647981787
88287.171875,9.99772215,0.825712216766117,28.8710565302838
87693.84765625,9.998724,0.824168893302638,28.8170941714209
86927.015625,9.99864385,0.822606135767713,28.7624522995704
86254.36328125,9.999042,0.820980612779777,28.7056158314607
85616.1484375,9.99859285,0.819324245756823,28.6477009005882
85013.6875,9.9987645,0.817855083452212,28.5963315892382
84325.90625,9.99913215,0.816176040253942,28.5376237851029
83708.64453125,9.9984894,0.814668045859785,28.4848967083841
82901.82421875,9.999403,0.812920246313702,28.4237848361434
82223.40234375,9.9986916,0.811171946250481,28.3626554633035
81595.51171875,9.9993629,0.809403121147699,28.3008084317377
81017.6328125,10.00003625,0.807933867943585,28.2494359420834
80424.91796875,9.99968815,0.806337093875468,28.1936046809604
79727.11328125,9.9997454,0.804505159629574,28.1295510359991
79119.3515625,9.99907875,0.802905240970217,28.0736098241335
78417.0078125,9.99983975,0.800982438217229,28.0063789586444
77743.83203125,9.9999943,0.799086615153626,27.940091438938
76981.4921875,9.9997749,0.797174824354292,27.8732456067934
76358.84765625,10.00027795,0.795143150540374,27.8022080608522
75740.74609375,9.99992035,0.793452794211872,27.7431046927228
75048.2109375,9.9998288,0.791415397373625,27.6718670410358
74326.02734375,10.0006599,0.789382397169449,27.6007831178129
73657.9453125,10.00034665,0.78729072161769,27.5276476090101
72950.4453125,9.99979925,0.78510570201268,27.4512483221217
72248.296875,10.0007367,0.782955068629876,27.376051350695
71525.7265625,10.0011764,0.780831813536735,27.3018116621236
70893.03515625,10.000545,0.778623927879241,27.2246128629105
70220.265625,10.00055455,0.776688614444582,27.1569445609994
69567.609375,10.00029135,0.774371957213709,27.0759425599199
68770.3359375,10.0006032,0.771748958660497,26.9842293237936
68018.30078125,10.0002527,0.769443492842681,26.903618630863
67330.5859375,10.0008297,0.766968289453489,26.8170730578143
66682.73046875,10.0007324,0.764879413527466,26.7440354380233
66035.1328125,10.0005674,0.762361667141441,26.6560023476028
65352.61328125,10.0009861,0.759834443128012,26.5676378716088
64674.470703125,10.00180295,0.757266534830578,26.477850868202
64031.943359375,10.00143485,0.754660890698402,26.3867444300141
63368.974609375,10.00111295,0.75235572995575,26.3061444040472
62696.7890625,10.0010443,0.749704110402983,26.2134304336707
62083.9765625,10.0011158,0.747353974051407,26.1312578339653
61321.91796875,10.00105,0.744539259517062,26.0328412418553
60708.525390625,10.00084305,0.741706647114273,25.9337988501494
60065.6484375,10.0013175,0.739274597529514,25.8487621513816
59273.375,10.0010719,0.735930093549259,25.7318214527713
58585.970703125,10.0021772,0.732864832339321,25.6246444873888
57863.7265625,10.0011463,0.729835828136933,25.5187352495431
57216.142578125,10.0017662,0.726677217550146,25.4082943199352
56498.357421875,10.0014615,0.723553277177245,25.299065635568
55830.40625,10.0021386,0.720245234908393,25.1833998219718
55122.78515625,10.0018854,0.717491074075222,25.0871004921406
54540.0546875,10.0017185,0.714083139325438,24.9679419344559
53892.376953125,10.00243475,0.711147946217427,24.8653128048051
53170.099609375,10.0016766,0.70766308518327,24.7434645168975
52457.953125,10.0021448,0.704068553759064,24.6177815999673
51819.716796875,10.00201845,0.700428419398801,24.4905041747833
51176.93359375,10.00114345,0.696731256548385,24.361232746447
50454.88671875,10.00210095,0.692897139220511,24.2271727000179
49831.787109375,10.0013313,0.689662186843053,24.1140624770298
49134.119140625,10.0014944,0.685664480646741,23.9742825400958
48456.837890625,10.0017819,0.681622330149276,23.832948606618
47808.88671875,10.00218965,0.678058002490653,23.7083217654074
47145.806640625,10.0020747,0.673859728441092,23.5615289664717
46403.380859375,10.0026474,0.66951398671813,23.4095799551794
45840.431640625,10.0023222,0.665783648907782,23.2791485632092
45128.19921875,10.00215625,0.661331608179591,23.1234828034822
44425.771484375,10.00276855,0.656752886281556,22.9633876322222
43752.744140625,10.00211575,0.652756681456621,22.8236601907909
43094.607421875,10.0024495,0.647226939871834,22.6303125829313
42486.77734375,10.00243615,0.642984970683156,22.4819919819285
41749.47265625,10.00145055,0.638065435928847,22.3099802772324
41156.607421875,10.0022712,0.633586050456114,22.1533584075564
40449.072265625,10.0025072,0.628372236718659,21.9710572279251
39786.61328125,10.0017233,0.623048305517014,21.7849057873082
39178.40625,10.00182485,0.618328670359538,21.6198835790048
38450.859375,10.0013514,0.612696583645258,21.4229574701139
37862.982421875,10.0024338,0.607770005135572,21.2506994802648
37245.052734375,10.0018754,0.602733786383867,21.0746079155198
36542.59375,10.0018196,0.596769591102798,20.8660696189789
35959.806640625,10.00238655,0.591459854076608,20.6804144782031
35277.14453125,10.00182625,0.585200845469292,20.4615680234018
34574.296875,10.0021477,0.578789883039573,20.2374084978872
33892.103515625,10.00207755,0.572195133641513,20.0068228545984
33299.12890625,10.0019512,0.566361534083047,19.8028508420646
32576.564453125,10.0019741,0.559491333334056,19.5626340326593
31913.8974609375,10.00210285,0.552393146913597,19.3144456962796
31261.408203125,10.00267985,0.545152184946114,19.0612652079061
30537.73046875,10.0021086,0.538748154523034,18.8373480602459
29818.1015625,10.0025692,0.531154406606467,18.5718323988275
29208.810546875,10.0019374,0.5232845386001,18.2966621888147
28569.80859375,10.00218155,0.515292654605565,18.0172256855093
27875.361328125,10.00245765,0.507044880602921,17.7288419791231
27196.5283203125,10.00205325,0.499784133249996,17.4749696940558
26512.4462890625,10.00212335,0.491180841553037,17.1741552990572
25853.001953125,10.0020771,0.482357741825608,16.8656553085877
25163.533203125,10.00207615,0.473317769064595,16.5495723449159
24519.51953125,10.0020094,0.465356905942345,16.2712204874946
23835.2802734375,10.0023766,0.457259424214939,15.9880917557671
23206.212890625,10.0026188,0.447575299492815,15.6494859962523
22482.3203125,10.00253055,0.437724719022019,15.305060105665
21867.6484375,10.00269985,0.427513071632932,14.948009497655
21188.4453125,10.00266075,0.417175871622863,14.5865689378623
20504.5888671875,10.00205565,0.408087641037853,14.2687986376872
19830.2978515625,10.0028534,0.397241023529402,13.8895462772518
19101.1357421875,10.00304695,0.386169522783481,13.5024308665553
18512.046875,10.00321675,0.376491381826011,13.1640343295808
17798.3525390625,10.00265265,0.364986777928022,12.7617754520287
17088.869140625,10.0022783,0.353232142987035,12.3507742303159
16419.640625,10.0036745,0.341163599170321,11.9287971737874
15700.7260742187,10.00303315,0.3289234351082,11.5008194093776
14951.6430664062,10.0027609,0.316415245919561,11.0634701370476
14337.3510742187,10.00338315,0.303673221776855,10.6179448173726
13598.51171875,10.0023079,0.290677169095362,10.1635373809567
12903.6328125,10.0028181,0.27554955859534,9.63459995088601
12299.3818359375,10.0031042,0.264002853358213,9.23086899853892
11540.486328125,10.0025597,0.250338329657621,8.75308844956717
10871.3364257813,10.00317715,0.236477594012514,8.26844734309489
10252.2114257813,10.00318765,0.224391431247205,7.84585423941276
9617.96044921875,10.00229885,0.212186145019924,7.41909597971762
8948.89013671875,10.00351095,0.197764536905406,6.91484394774147
8313.98486328125,10.00327445,0.185248250552507,6.47721155777997
7594.54174804687,10.0025501,0.170489814682985,5.9611823315729
6960.11645507812,10.00334405,0.155564108076023,5.43930447818262
6330.33837890625,10.0036583,0.1426482257766,4.98770020197902
5705.70190429687,10.00356055,0.127441612439886,4.45600043496105
4901.07421875,10.0036087,0.112111167110975,3.91997087800612
4341.3271484375,10.0037928,0.0988839560214111,3.45748097976962
3681.37561035156,10.003561,0.0833419476948726,2.91405411520533
3026.15698242188,10.003397,0.0699643371247715,2.44630549387313
2301.17626953125,10.00315,0.0542935242008835,1.89837497205886
1741.03930664062,10.00316715,0.040789142463703,1.42619379243717
835.201232910156,10.003582,0.0204488240508062,0.714993847930287
124.995307922363,10.00281665,0.00460892202805876,0.161151119862194
-1121.12811279297,10.0032291,-0.0224594741194832,-0.785296297884028
-1737.10919189453,10.0029812,-0.0381406652766018,-1.33358969498608
-2488.3095703125,10.0031309,-0.0537812632058101,-1.8804637484549
-3163.64819335937,10.0018244,-0.0694300437861065,-2.42762390860512
-3735.04064941406,10.00224065,-0.0828130050386826,-2.89555961673715
-4376.3310546875,10.0023384,-0.0983595515966257,-3.43914516072118
-5412.16259765625,10.0016451,-0.118179601098611,-4.13215388456682
-6037.30151367187,10.001503,-0.133460604151785,-4.66645469062185
-6677.29541015625,10.0020189,-0.146449518813889,-5.12061254594017
-7367.2724609375,10.00192025,-0.161454927412472,-5.64527718225427
-8107.39208984375,10.0017414,-0.176303074631351,-6.16444316892836
-8777.95849609375,10.0013852,-0.193125658775227,-6.75264541172122
-9567.7431640625,10.0016665,-0.209654288781711,-7.33056953782206
-10327.5288085938,10.0010128,-0.22394644206267,-7.83029517701643
-11057.353515625,10.0010357,-0.238011165581518,-8.3220687266265
-11757.5625,10.00094175,-0.25187085668808,-8.80667331077203
-12412.1000976563,10.00111485,-0.265513426440432,-9.28368623917594
-13092.2836914062,10.00023555,-0.278961551177757,-9.75390039083067
-13877.4326171875,9.99992605,-0.292154588203404,-10.2151953917274
-14587.0390625,9.9996834,-0.305118759327264,-10.6684880883659
-15286.68359375,10.0003357,-0.31784500433582,-11.1134616900636
-15866.9721679687,9.99943925,-0.330342524862233,-11.5504379322459
-16607.595703125,9.9998617,-0.340828004413641,-11.9170630913861
-17183.1826171875,9.999886,-0.352899074425085,-12.3391284764016
-17868.73828125,10.0005455,-0.363013991804577,-12.692796916244
-18529.17578125,9.9999757,-0.374614431628898,-13.0984067003111
-19279.9912109375,9.9994974,-0.385979151458396,-13.4957745265173
-19880.388671875,9.99973345,-0.39706952224591,-13.883549728878
-20646.0751953125,10.0001106,-0.407899623489572,-14.2622245975375
-21311.802734375,9.9990377,-0.417033921565701,-14.5816056491504
-21892.5068359375,9.9997802,-0.42743884434227,-14.9454141378416
-22678.294921875,9.99908165,-0.437615518696339,-15.3012419124594
-23303.705078125,9.9987373,-0.447487069254928,-15.6464010228996
-23974.17578125,9.99881555,-0.457194359487985,-15.9858167653142
-24600.1337890625,9.99927905,-0.465313161125521,-16.2696909484448
-25270.41015625,9.99845505,-0.473261318591528,-16.5475985521513
-25936.35546875,9.99844505,-0.482319111175878,-16.8643045865692
-26607.3935546875,9.9981313,-0.491136380354292,-17.1726007116885
-27252.8955078125,9.99824095,-0.498551165480983,-17.4318589329015
-27973.466796875,9.9983759,-0.508207208845608,-17.7694828267695
-28628.84765625,9.9989915,-0.515237648933959,-18.0153024102783
-29239.28515625,9.99867965,-0.522183697945313,-18.2581712568291
-29944.9140625,9.99864245,-0.530061981916248,-18.5336357313373
-30650.6640625,9.9985652,-0.537727483513423,-18.8016602627071
-31291.5673828125,9.99856615,-0.545184636084046,-19.0623998630785
-31991.9033203125,9.9983201,-0.552488531383943,-19.3177808176204
-32622.5283203125,9.9983549,-0.558525314773984,-19.5288571599295
-33313.05859375,9.9977951,-0.565561175266554,-19.7748662680613
-33943.2734375,9.99792055,-0.571361061622033,-19.9776594972739
-34609.017578125,9.9980359,-0.577973816234979,-20.2088746935307
-35199.76171875,9.9984789,-0.583550254731383,-20.4038550605379
-35965.173828125,9.9979982,-0.589891869190705,-20.6255898318428
-36575.724609375,9.99793385,-0.595185752263288,-20.8106906385765
-37226.15234375,9.9990807,-0.601284673385635,-21.0239396288684
-37926.859375,9.99776315,-0.607181353530005,-21.2301172562939
-38657.357421875,9.998682,-0.612950234046848,-21.4318263652744
-39258.064453125,9.99758335,-0.617749458674638,-21.5996314221901
-39853.9765625,9.9977088,-0.622466735295387,-21.7645711641744
-40614.380859375,9.9981108,-0.62784341916387,-21.9525671036318
-41194.931640625,9.99788335,-0.633112482757602,-22.1368000964196
-41805.599609375,9.99760915,-0.637575193635761,-22.2928389383133
-42560.93359375,9.9977751,-0.642583141617505,-22.4679420145981
-43216.560546875,9.99716855,-0.646824087117192,-22.6162268222794
-43912.572265625,9.99799535,-0.651632359383619,-22.7843482301965
-44608.26171875,9.9976206,-0.656316581235581,-22.9481322110343
-45198.625,9.9975333,-0.660950113707096,-23.1101438359124
-45909.3828125,9.9971485,-0.664806115927929,-23.2449690883891
-46549.6171875,9.9964905,-0.669203975266603,-23.3987403939372
-47290.455078125,9.9973154,-0.673546891590101,-23.5505906150385
-47971.017578125,9.9969702,-0.677718005352695,-23.6964337535907
-48621.728515625,9.9971209,-0.681902855334965,-23.8427571795442
-49292.158203125,9.9976745,-0.685948746582074,-23.9842219084641
-49967.658203125,9.99753525,-0.689322994285337,-24.1022025973894
-50653.083984375,9.9975786,-0.693225430449858,-24.2386514143307
-51313.61328125,9.99759435,-0.696990515748354,-24.3702977534389
-52104.359375,9.99807025,-0.700711580043549,-24.5004048966276
-52810.111328125,9.9971323,-0.704317874873183,-24.62649912144
-53405.646484375,9.9982524,-0.707940279247231,-24.753156617036
-54086.189453125,9.9982729,-0.710862554455131,-24.8553340718577
-54776.904296875,9.99785515,-0.714299322279484,-24.9755007790029
-55462.17578125,9.9975052,-0.717652026899949,-25.0927282132849
-56062.923828125,9.9977727,-0.720524776754078,-25.1931740123804
-56733.77734375,9.9982295,-0.723750583220603,-25.3059644482728
-57419.697265625,9.998065,-0.726951756256487,-25.4178935754016
-58080.02734375,9.998178,-0.729609213718101,-25.5108116684651
-58826.056640625,9.9972763,-0.73273771266119,-25.6201997433983
-59401.279296875,9.9971099,-0.735696861784318,-25.7236664959552
-60001.671875,9.9972658,-0.738206433669839,-25.8114137646797
-60677.513671875,9.9970613,-0.740738258884852,-25.899939121848
-61298.279296875,9.9976387,-0.743590296440897,-25.9996607147167
-61893.708984375,9.99754525,-0.745915200467016,-26.0809510652803
-62606.072265625,9.9979143,-0.74837231248252,-26.1668640728154
-63259.798828125,9.9977312,-0.751089792117476,-26.2618808432684
-63893.142578125,9.9981699,-0.753735794983347,-26.3543984259912
-64531.115234375,9.9979138,-0.756041933469116,-26.4350326387803
-65235.2578125,9.9974456,-0.758620152124769,-26.5251801442227
-65883.83984375,9.99733925,-0.760808955089622,-26.6017117164203
-66627.5546875,9.9980412,-0.763335757863624,-26.6900614637631
-67251.00390625,9.99735405,-0.765819296880251,-26.7768984923165
-67889.01953125,9.99796345,-0.767908401594611,-26.8499441116997
-68607.6484375,9.9980249,-0.77024574778487,-26.9316695029675
-69246.39453125,9.99797535,-0.772627987739074,-27.0149646062613
-69925.08984375,9.99795435,-0.774977839765453,-27.0971272645263
-70724.25,9.9969788,-0.777217391596245,-27.175433272596
-71403.05859375,9.99759485,-0.779508285742033,-27.2555344665046
-72076.5703125,9.9971814,-0.781689927645482,-27.3318156519399
-72800.32421875,9.99695585,-0.783863187264659,-27.4078037505125
-73458.76171875,9.9973888,-0.785958850531707,-27.4810786899198
-74112.80078125,9.9974518,-0.787748562295409,-27.543656024315
-74781.1484375,9.99765685,-0.789895995977229,-27.6187411180849
-75454.78515625,9.99826525,-0.791939868847837,-27.6902052044698
-76088.453125,9.99815225,-0.793652719716933,-27.7500950949976
-76711.3203125,9.99785325,-0.795401466960018,-27.8112401034971
-77480.65625,9.9973469,-0.797325535076722,-27.8785152124728
-78139.50390625,9.9977093,-0.799287448670588,-27.9471135898807
-78697.7890625,9.9979682,-0.800907589165896,-28.0037618589474
-79336.0390625,9.99789045,-0.802584643039465,-28.062400106275
-80135.3359375,9.9979391,-0.804683989092866,-28.1358038144359
-80834.171875,9.99782465,-0.806520012247692,-28.200000428241
-81417.00390625,9.9981475,-0.808044055327122,-28.2532886478015
-82130.9375,9.9976845,-0.809922056319955,-28.3189530181802
-82814.671875,9.9986305,-0.811410113400265,-28.3709829860232
-83533.125,9.9980364,-0.813163373298171,-28.4322857796563
-84106.421875,9.9978719,-0.814814248576087,-28.4900086914716
-84880.41015625,9.9980011,-0.816543167724878,-28.5504604099608
-85544.0703125,9.99773455,-0.817973301854535,-28.6004650998089
-86117.0078125,9.9979725,-0.819648157672085,-28.659026492031
-86780.375,9.99732305,-0.821295967913212,-28.7166422347277
-87403.70703125,9.99740075,-0.822634812764708,-28.763454991773
-88047.23046875,9.9971919,-0.824038395164306,-28.8125312994513
-88781.10546875,9.9959202,-0.825615054867767,-28.8676592611107
-89359.328125,9.9981723,-0.826954544395405,-28.9144945592799
-89931.1796875,9.9974499,-0.828508052935724,-28.9688130397106
-89422.8515625,9.99863145,-0.82734106686917,-28.9280093310899
-88715.5078125,9.99991605,-0.825775087261765,-28.8732547993624
-88038.0625,9.9987831,-0.824224985954906,-28.8190554529687
-87285.89453125,9.9982777,-0.822591397594993,-28.7619369788459
-86613.18359375,9.99917745,-0.820985819833795,-28.7057978962865
-85945.6484375,9.9991016,-0.819604024819868,-28.6574833853101
-85228.16015625,9.9994745,-0.81774254344109,-28.5923966238143
-84555.73828125,9.9992547,-0.815968660360108,-28.5303727398639
-83878.21875,9.9995346,-0.814349616714729,-28.4737628221933
-83275.4453125,9.99946165,-0.812837272628107,-28.4208836583254
-82552.69140625,10.0001998,-0.81114363669833,-28.3616656188227
-81919.859375,10.0003848,-0.809594586022017,-28.3075030077628
-81257.4375,9.9995909,-0.807865743212253,-28.2470539584704
-80540,10.0003567,-0.805988407124867,-28.1814128365338
-79912.046875,10.0000801,-0.804201346698515,-28.1189282062418
-79254.375,10.0005031,-0.802607293682229,-28.0631920867912
-78621.75390625,9.9994507,-0.80073050920337,-27.9975702518661
-77938.47265625,10.0006914,-0.799096975970719,-27.9404537052699
-77295.96875,10.00042055,-0.797200204394206,-27.8741330207764
-76433.83984375,10.0000868,-0.794924706574375,-27.7945701599432
-75871.09375,10.0002565,-0.793199922442786,-27.734263022475
-75098.78125,10.0005426,-0.791205109471301,-27.6645143171783
-74456.078125,10.0005889,-0.789246313644017,-27.596024952588
-73713.58203125,10.0009861,-0.787088657312291,-27.5205824235067
-73090.05859375,10.0008979,-0.784990178578155,-27.4472090411942
-72318.140625,10.0011644,-0.782809017611616,-27.3709446717348
-71645.4609375,10.00153685,-0.780321837007197,-27.283980314937
-70858.5390625,10.00112535,-0.778173813078725,-27.2088745831722
-70260.5703125,10.0017824,-0.775895852093727,-27.1292255976828
-69478.19921875,10.00198555,-0.773581936882058,-27.0483194714006
-68840.43359375,10.0014324,-0.771309456494258,-26.9688621151838
-68182.875,10.0014038,-0.769292453440224,-26.898337532875
-67485.1484375,10.0018325,-0.766845793268666,-26.8127899744289
-66837.734375,10.0015149,-0.764435193245437,-26.72850326033
-66085.51171875,10.0016203,-0.762001197219158,-26.6433985041664
-65477.705078125,10.00142,-0.759487861632922,-26.5555196375147
-64814.716796875,10.0020661,-0.757318021245039,-26.4796510924839
-64117.349609375,10.00179575,-0.754693588862334,-26.3878877224592
-63479.677734375,10.00141905,-0.752006978033791,-26.2939502809018
-62806.87890625,10.00177765,-0.749754458207171,-26.2151908464046
-62094.740234375,10.00143765,-0.747053066217264,-26.1207365810232
-61486.876953125,10.00182105,-0.744203712161844,-26.0211088168477
-60744.283203125,10.0022645,-0.741472617791735,-25.925616006704
-60116.150390625,10.00244715,-0.73895365762424,-25.837540476372
-59418.7421875,10.00229455,-0.736014116704702,-25.7347593253392
-58706.099609375,10.00138475,-0.732611743872749,-25.6157952403059
-58053.875,10.0017457,-0.730010598020548,-25.5248460846345
-57470.728515625,10.0019608,-0.727304488091482,-25.4302268563455
-56763.431640625,10.0026116,-0.724136336564841,-25.319452327442
-56160.1328125,10.00214295,-0.721440491829923,-25.2251920220253
-55532.306640625,10.00232075,-0.718637168447387,-25.1271737219366
-54774.921875,10.0018954,-0.714824900088555,-24.9938776254739
-54027.46875,10.00219535,-0.711443121665561,-24.87563362467
-53370.03125,10.0020704,-0.707962422188976,-24.7539308457684
-52647.779296875,10.0025196,-0.704359452974855,-24.6279529012187
-52024.703125,10.0007486,-0.700796835310531,-24.5033858500186
-51372.009765625,10.00105955,-0.69764082257489,-24.3930357543668
-50570.103515625,10.00274135,-0.693280716481974,-24.2405844923767
-49942.3125,10.002861,-0.690040182463663,-24.1272791071211
-49239.96484375,10.00247145,-0.685442553755359,-23.966522858579
-48582.3203125,10.0026569,-0.682101846609277,-23.8497149164083
-47840.021484375,10.00260875,-0.677965737226984,-23.7050957072372
-47222.064453125,10.0019989,-0.673768466549332,-23.5583379912354
-46430.0859375,10.0013895,-0.669518197981064,-23.4097272021351
-45792.478515625,10.00260735,-0.665113163662443,-23.2557050231623
-45144.794921875,10.00393915,-0.66062592981703,-23.0988087348612
-44457.279296875,10.00242425,-0.656746333737998,-22.9631585223076
-43759.751953125,10.00283525,-0.651350579043116,-22.7744957707383
-42957.474609375,10.0017171,-0.646535026549832,-22.6061198094347
-42379.31640625,10.0020852,-0.642318192259392,-22.4586780510277
-41706.646484375,10.0024114,-0.637273461308294,-22.2822888569334
-41019.232421875,10.0020628,-0.63223714788958,-22.1061939821531
-40316.728515625,10.00268985,-0.62691242773112,-21.9200149556336
-39684.40625,10.0025687,-0.621539319065034,-21.7321440232529
-38976.3359375,10.0030112,-0.616816560797258,-21.5670126152887
-38383.3203125,10.0024171,-0.611177056396605,-21.3698271467344
-37755.84765625,10.00280905,-0.606234049869049,-21.196994750666
-36953.736328125,10.0019636,-0.600417035883032,-20.9936026532529
-36296.015625,10.00279425,-0.59429510953012,-20.7795492842699
-35588.83203125,10.0034585,-0.588137784336408,-20.5642581935807
-35015.80859375,10.0030737,-0.582678447779828,-20.373372299994
-34333.001953125,10.00302505,-0.576204461358537,-20.1470091384104
-33700.779296875,10.00280715,-0.569579992326011,-19.9153843470633
-33063.0546875,10.00255485,-0.563711907234517,-19.7102065466614
-32290.490234375,10.0025473,-0.556754062911058,-19.4669252766104
-31707.4345703125,10.00261165,-0.549579563981046,-19.2160686706659
-30950.4990234375,10.00320575,-0.542302284901876,-18.9616183532124
-30210.927734375,10.0031118,-0.534761413098219,-18.6979515069307
-29596.7490234375,10.00302695,-0.527101129907436,-18.4301094373229
-28813.0576171875,10.0028868,-0.519200278553039,-18.1538558934629
-28118.818359375,10.002655,-0.511076581553765,-17.8698105438379
-27519.66015625,10.0025468,-0.502737018548208,-17.5782174317555
-26690.978515625,10.0031023,-0.494219021454631,-17.2803853655465
-26001.3662109375,10.0027361,-0.485473392323186,-16.9745941371743
-25312.00390625,10.00216865,-0.476528427174936,-16.6618331180048
-24668.1103515625,10.00201795,-0.467298589496464,-16.3391115208554
-24019.0810546875,10.0018225,-0.457883812012822,-16.0099234969518
-23220.326171875,10.003057,-0.448282779628353,-15.6742230639284
-22486.37890625,10.0024509,-0.438376129357495,-15.3278366908215
-21862.0205078125,10.00286535,-0.42826023872805,-14.9741342212605
-21002.6923828125,10.0025949,-0.416420792180704,-14.5601675587659
-20283.7724609375,10.0024548,-0.404241709347374,-14.1343255016564
-19614.75390625,10.0019879,-0.394893162526818,-13.8074532352034
-18960.4609375,10.00247525,-0.383810127763932,-13.4199345372004
-18331.4609375,10.0022655,-0.372447350136747,-13.022634620166
-17687.21484375,10.002995,-0.36252437884332,-12.6756775819343
-17008.0322265625,10.0021896,-0.350698658704461,-12.2621908637923
-16338.8999023438,10.00252345,-0.340365340771432,-11.9008860409592
-15580.12109375,10.0024977,-0.326318345856837,-11.4097323726167
-14800.8974609375,10.0020332,-0.311951323713433,-10.9073889410291
-14167.357421875,10.0018263,-0.300982855339458,-10.5238760608202
-13453.1333007813,10.0029831,-0.287954373197299,-10.0683347271783
-12678.5541992187,10.0026255,-0.272775970414835,-9.53762134317605
-11999.5219726563,10.0033569,-0.261228022586289,-9.13384694357654
-11300.7250976562,10.0031776,-0.245530114799752,-8.58496904894238
-10606.3989257813,10.003068,-0.231605240090896,-8.0980853178635
-9992.3642578125,10.0025029,-0.219512610737822,-7.67526610971406
-9313.275390625,10.00243425,-0.205177163422143,-7.17402669308192
-8523.71142578125,10.0020351,-0.190658057533361,-6.66636564801961
-7944.33422851562,10.001976,-0.175967209526871,-6.15269963380668
-7239.82373046875,10.00259305,-0.16112276331406,-5.63366305293916
-6425.5615234375,10.0022974,-0.146081701594841,-5.10775180401542
-5835.81909179688,10.00309135,-0.130931202176203,-4.578014062105
-5011.53588867188,10.0023136,-0.113440378513359,-3.9664468011664
-4381.66088867188,10.0025015,-0.100222295203095,-3.50427605605227
-3736.47912597656,10.0023427,-0.0846923346820254,-2.96127044342746
-3071.52478027344,10.00252435,-0.0713252371476653,-2.49388941075753
-2451.51647949219,10.0024333,-0.0556669379891996,-1.9463964331888
-1751.33941650391,10.00210475,-0.0399239196182532,-1.39594124539347
-745.393402099609,10.0026393,-0.0173329657467878,-0.606047753384189
-64.9757146835327,10.00230745,-0.00375159177739898,-0.131174537671293
1185.55578613281,10.0029144,0.0255356165968371,0.892853727162136
1746.75750732422,10.0023599,0.038968686070988,1.36254147101357
2478.07287597656,10.0019875,0.0545945725061776,1.90890113657964
3083.47094726562,10.0023689,0.0679974195429778,2.37753215185237
3770.05004882812,10.0017819,0.0836232133997404,2.9238885804105
4476.49194335937,10.0014424,0.0991536707793429,3.46691156571129
5447.13012695313,10.00080295,0.118945564249348,4.15893581291426
6082.12280273437,10.00104905,0.134206517605102,4.69253558059797
6737.24536132813,10.00078775,0.149331500023986,5.22138111971979
7532.2646484375,10.0015063,0.166445539089214,5.81977409402846
8147.3720703125,10.00090695,0.179151567196784,6.26404081107636
8847.79541015625,10.00088355,0.193824318451506,6.77707407173098
9587.7412109375,10.0006495,0.2082848738616,7.28268789725874
10247.546875,10.0003214,0.220546172988251,7.71140464993885
10852.7250976562,10.00013875,0.234648528795449,8.20449401382689
11522.5434570312,10.00097515,0.248554070552937,8.69070176758521
12252.5068359375,10.00015785,0.260305234192743,9.10158161513087
12842.6606445313,10.00019455,0.273842023768463,9.57489593596025
13607.8486328125,9.99971055,0.28713597590941,10.039719437392
14207.6884765625,9.99947975,0.298284912372816,10.4295423906579
14972.7080078125,9.9999495,0.312949661804795,10.9422958673005
15527.390625,9.9994831,0.323769115014269,11.3205984270723
16277.9575195313,9.9994316,0.33613697150474,11.7530409617042
16988.775390625,9.9988527,0.348269133484107,12.1772424295142
17604.6005859375,9.99920845,0.358460721294168,12.5335916536422
18260.2998046875,9.9990616,0.370145786211826,12.9421603570569
19055.79296875,9.9990692,0.381551022370698,13.3409448381363
19656.1435546875,9.99910405,0.392774277595163,13.7333663494812
20287.146484375,9.9992728,0.402141505719785,14.0608918083841
21042.4765625,9.9990387,0.414386852555264,14.4890507886456
21668.4296875,9.9985905,0.423362649492167,14.8028898423835
22328.9970703125,9.99877645,0.433603919017802,15.1609761894336
23039.556640625,9.9980936,0.442188101958685,15.4611224461079
23645.2880859375,9.9981165,0.45200134853237,15.8042429556773
24356.2109375,9.9984436,0.460219983516185,16.0916078152512
24956.384765625,9.99765155,0.46955851043873,16.4181297356199
25657.134765625,9.99865535,0.478695607097059,16.7376086397573
26373.2138671875,9.99819375,0.48764830240365,17.0506399441836
27119.06640625,9.9985065,0.496359740034213,17.3552356655319
27719.35546875,9.99770355,0.504810185481319,17.6507057860601
28365.0966796875,9.99845695,0.511933787096785,17.8997827656219
29040.697265625,9.9978385,0.520045647506433,18.1834142484767
29781.50390625,9.9981971,0.527962314822662,18.4602207979952
30427.1884765625,9.9976306,0.535678359632146,18.7300125745506
31042.912109375,9.9970813,0.542108955740629,18.9548585923297
31743.736328125,9.9979,0.549476389358212,19.212461166371
32389.2646484375,9.99801545,0.555623044860661,19.4273791909322
33114.927734375,9.9974632,0.562656804408431,19.6733148394556
33790.341796875,9.9974871,0.569540755764222,19.9140124393085
34371.16796875,9.9978671,0.575257353393626,20.1138934753016
35081.57421875,9.9976125,0.581783576028769,20.342083077929
35862.39453125,9.9970574,0.589033896208797,20.5955907765314
36467.958984375,9.9980292,0.594340089755393,20.7811220194193
37163.576171875,9.9961824,0.599558831972553,20.9635955235158
37764.193359375,9.9974923,0.605529507024832,21.1723603854836
38444.638671875,9.99733925,0.61129446789599,21.3739324439157
39115.552734375,9.99778315,0.616977975690266,21.5726564926666
39841.3828125,9.99726535,0.622507679563701,21.7660027819476
40451.984375,9.99735595,0.627129225386514,21.9275952932348
41082.44921875,9.99756575,0.631617276459358,22.0845201559216
41873.041015625,9.9971685,0.637509580300062,22.2905447657364
42473.6953125,9.99755005,0.641855463107436,22.4424987100502
43199.58203125,9.9975529,0.646767413667811,22.6142452331402
43870.478515625,9.99727345,0.651607824271665,22.7834903591491
44546.068359375,9.99806075,0.656304702312466,22.9477168640722
45376.78515625,9.9970627,0.661572812497357,23.1319165208866
45992.337890625,9.9968462,0.665391035979218,23.2654208384342
46667.904296875,9.9981446,0.669766594691964,23.4184124018169
47283.6171875,9.9977956,0.673456273843549,23.5474221623618
48009.66796875,9.9974785,0.677659031996669,23.6943717481353
48565.1328125,9.99800255,0.681213433543233,23.8186515224907
49205.765625,9.9979997,0.684725697430227,23.9414579521058
49891.54296875,9.9984336,0.688631378940945,24.0780202426904
50501.833984375,9.99831105,0.692056934621138,24.197794916823
51252.556640625,9.9973736,0.695789521412611,24.3283049444969
51867.955078125,9.9972949,0.699570820051571,24.4605181836214
52548.8515625,9.99749375,0.703240514358734,24.5888291733823
53249.578125,9.9980707,0.70680172557522,24.7133470480846
53880.123046875,9.997282,0.709813057448081,24.8186383723105
54635.705078125,9.9970798,0.713285244423239,24.9400435113021
55216.115234375,9.99771595,0.716130590557599,25.0395311383776
55811.712890625,9.9984069,0.719490526059667,25.1570114006877
56502.49609375,9.9974761,0.72224223802122,25.2532251056371
57153.244140625,9.997983,0.725429958674722,25.3646838697455
57793.671875,9.99810885,0.728153976914934,25.4599292627599
58444.154296875,9.9979653,0.731207565514721,25.5666980949203
59199.947265625,9.99801255,0.734278113542036,25.6740599140572
59780.43359375,9.9982071,0.736806493993591,25.7624648249507
60475.95703125,9.9993348,0.739728075203853,25.8646180141207
61207.060546875,9.9974008,0.742575837250039,25.9641901136377
61857.7421875,9.997221,0.745359238570818,26.0615118381405
62514.267578125,9.997787,0.748201298320801,26.1608845566714
63213.1484375,9.99803165,0.750537519215761,26.2425706019497
63811.36328125,9.9979405,0.752758337410093,26.3202215877655
64530.5,9.998147,0.755451919492414,26.414402779455
65088.287109375,9.9984813,0.757734414638138,26.4942103020328
65731.8125,9.99846175,0.759909786824653,26.5702722665963
66365.140625,9.9983573,0.762467687349028,26.6597093478681
67104.43359375,9.9973955,0.764948200942621,26.7464405923993
67837.92578125,9.99838875,0.7673722494049,26.8311975316399
68425.625,9.9979658,0.769406680222521,26.9023314763119
69144.9140625,9.9980278,0.771780834742793,26.9853438721256
69888.75,9.9981203,0.77413241305474,27.0675668900259
70507.109375,9.9986062,0.776425127115338,27.1477317173195
71145.7734375,9.9978695,0.778393852009084,27.2165682520659
71844.25390625,9.99810455,0.780545845644696,27.2918127847796
72462.37890625,9.9982777,0.782682339760936,27.3665153762565
73206.35546875,9.9983277,0.784899096446722,27.444024351284
73799.94921875,9.9990802,0.78666917198971,27.5059151045353
74528.67578125,9.9983249,0.788820439610534,27.5811342521166
75247.4296875,9.9977641,0.790833269004222,27.6515129022455
75971.33984375,9.9976854,0.792917284273358,27.7243805689985
76554.546875,9.998271,0.794606944796972,27.7834596082857
77328.44140625,9.999155,0.796585827646332,27.8526513163053
77977.05078125,9.99790955,0.798504391278654,27.9197339607921
78696.61328125,9.9979038,0.800457528701626,27.9880254790778
79299.3515625,9.99859905,0.802043500578518,28.0434790412069
79952.8515625,9.99841355,0.803926574454115,28.1093207851089
80606.2890625,9.9982476,0.805475883892727,28.1634924438016
81360.16015625,9.9980507,0.80761685915415,28.2383517186766
81998.78515625,9.9984207,0.80913277260569,28.2913556855136
82672.79296875,9.99836875,0.81090896441277,28.3534602941528
83280.8515625,9.99762105,0.812410050751245,28.4059458304631
83994.64453125,9.9979601,0.814143921091832,28.4665706675466
84612.91796875,9.99825005,0.815644775835545,28.5190481061379
85291.6015625,9.9975815,0.817275953287349,28.5760822827744
85924.8203125,9.9974656,0.818748705613573,28.6275771193557
86643.890625,9.99817755,0.820375495440763,28.6844578825442
87292.18359375,9.9980903,0.822015323939578,28.7417945433419
87905.33984375,9.9976449,0.823353377101597,28.788579618937
88583.9609375,9.9978509,0.824933503809212,28.8438288045179
89373.34765625,9.9980736,0.826545402042689,28.9001888826115
90003.9140625,9.9980197,0.827987287150437,28.9506044458195