File: M16M-MT01.csv
Temperature (K),Magnetic Field (Oe),Moment (emu),M (emu/g)
2.00059945,99.7514266967773,0.00957250782448658,0.334703070786244
2.3612232,99.7514266967773,0.00836199520325864,0.292377454659393
2.76212775,99.7514266967773,0.00733301483692946,0.256399120172359
3.1620102,99.7514266967773,0.00653838693635549,0.228614927844598
3.59511675,99.7514266967773,0.00584825721226301,0.204484517911294
3.9919243,99.7514266967773,0.00533296768288737,0.186467401499558
4.3837633,99.7514266967773,0.00490004224850191,0.171330148549018
4.78135205,99.7514266967773,0.00453228519259844,0.158471510230715
5.1845992,99.7514266967773,0.00421524006998098,0.147386016432901
5.590121,99.7514266967773,0.00394080438955466,0.137790363271142
6.05414245,99.7514266967773,0.00366199798769034,0.12804188768148
6.45009705,99.7514266967773,0.00345188588619378,0.120695310706076
6.8525677,99.7514266967773,0.0032605477619558,0.114005166501951
7.2389226,99.7514266967773,0.00309215352452266,0.108117256102191
7.64824295,99.7514266967773,0.00293682152211877,0.10268606720695
8.05365035,99.7514266967773,0.00279464728045836,0.0977149398761664
8.44870615,99.7514266967773,0.00266657086083655,0.0932367433858933
8.84673405,99.7514266967773,0.00254909929293655,0.0891293459068724
9.2468963,99.7514266967773,0.0024381260175433,0.0852491614525629
9.62941555,99.7514266967773,0.0023381681402152,0.0817541307767552
10.03149555,99.7514266967773,0.00224493673080174,0.0784942912867741
10.4382944,99.7514266967773,0.00215792589216653,0.075451954271557
10.83561565,99.7514266967773,0.00207706352920041,0.0726245989230913
11.23238275,99.7514266967773,0.00200114857280548,0.0699702298183734
11.66717765,99.7514266967773,0.00192465559817283,0.0672956502857633
12.0862975,99.7514266967773,0.00185322912627608,0.0647982211984643
12.49789765,99.7514266967773,0.00179176647378726,0.0626491774051489
12.8933988,99.7514266967773,0.00173363798777815,0.0606167128593759
13.28701735,99.7514266967773,0.001678781875804,0.0586986669861538
13.6849227,99.7514266967773,0.00162685261419894,0.0568829585384245
14.08875465,99.7514266967773,0.00157802841027815,0.055175818541194
14.49186565,99.7514266967773,0.00153186398606979,0.053561677834608
14.8877497,99.7514266967773,0.00148814011711553,0.0520328712278157
15.27033565,99.7514266967773,0.00144637714778527,0.0505726275449395
15.69283625,99.7514266967773,0.00140357316598655,0.0490759848247045
16.10418415,99.7514266967773,0.00136637291433568,0.0477752767250238
16.50809,99.7514266967773,0.0013309140027167,0.0465354546404441
16.91196825,99.7514266967773,0.00129712357710196,0.0453539712273413
17.2988224,99.7514266967773,0.00126472921874,0.0442213013545455
17.7004633,99.7514266967773,0.00123418115809262,0.0431531873458958
18.09379385,99.7514266967773,0.00120461625203152,0.0421194493717315
18.4916096,99.7514266967773,0.00117681717525155,0.0411474536801241
18.88923265,99.7514266967773,0.00115013559312083,0.040214531228001
19.28756425,99.7514266967773,0.00112405685270916,0.0393026871576629
19.689168,99.7514266967773,0.00109923408040226,0.0384347580560231
20.0862474,99.7514266967773,0.00107571085705327,0.0376122677291353
20.4815073,99.7514266967773,0.00105316200129109,0.0368238461989892
20.88300515,99.7514266967773,0.00103158698532305,0.0360694750112955
21.2765436,99.7514266967773,0.00101081777470962,0.0353432788360007
21.6739502,99.7514266967773,9.91037210624114E-4,0.0346516507211229
22.1089859,99.7514266967773,9.69729545765827E-4,0.0339066274743296
22.5067921,99.7514266967773,9.51795155604404E-4,0.0332795508952589
22.9047499,99.7514266967773,9.33832420565668E-4,0.0326514832365618
23.30396935,99.7514266967773,9.16640525062664E-4,0.0320503680091841
23.7015505,99.7514266967773,9.00151820357113E-4,0.0314738398726263
24.0979071,99.7514266967773,8.8394726085284E-4,0.0309072468829664
24.4956856,99.7514266967773,8.6861682544891E-4,0.0303712176730388
24.92855645,99.7514266967773,8.52551860524719E-4,0.0298095056127524
25.32490065,99.7514266967773,8.38229923166028E-4,0.0293087385722387
25.72066025,99.7514266967773,8.24685638418513E-4,0.0288351621824655
26.11852265,99.7514266967773,8.11142247559906E-4,0.0283616170475492
26.51550675,99.7514266967773,7.98234696291033E-4,0.02791030406612
26.91154285,99.7514266967773,7.85787863731467E-4,0.0274751001304709
27.30968475,99.7514266967773,7.73605420273769E-4,0.0270491405690129
27.7115631,99.7514266967773,7.61873424055309E-4,0.0266389309110248
28.10240265,99.7514266967773,7.50304247796577E-4,0.0262344142586216
28.50231265,99.7514266967773,7.39436832049736E-4,0.0258544346870537
28.9086075,99.7514266967773,7.28697530286104E-4,0.0254789346253882
29.30266095,99.7514266967773,7.18367905982397E-4,0.0251177589504335
29.6922874,99.7514266967773,7.0823718197558E-4,0.024763537831314
30.0996542,99.7514266967773,6.98349706530172E-4,0.0244178219066494
30.4944477,99.7514266967773,6.88761518802569E-4,0.0240825705875024
30.89054585,99.7514266967773,6.7960165561279E-4,0.0237622956507969
31.2816515,99.7514266967773,6.70569818536988E-4,0.0234464971516429
31.67994115,99.7514266967773,6.61847758058432E-4,0.0231415300020431
32.0831585,99.7514266967773,6.5334418962836E-4,0.022844202434558
32.46813205,99.7514266967773,6.44934181831076E-4,0.0225501462178698
32.85769655,99.7514266967773,6.37124833457111E-4,0.02227709207892
33.2603893,99.7514266967773,6.29132816599129E-4,0.0219976509300395
33.6626625,99.7514266967773,6.21586785022833E-4,0.021733803672127
34.0664997,99.7514266967773,6.13740885874789E-4,0.0214594715340835
34.4478111,99.7514266967773,6.06708291452503E-4,0.0212135766242134
34.86105345,99.7514266967773,5.99830188846673E-4,0.0209730835261075
35.25315665,99.7514266967773,5.92835680860456E-4,0.0207285203098062
35.6396637,99.7514266967773,5.85955938363209E-4,0.0204879698728395
36.04114915,99.7514266967773,5.79157518635781E-4,0.020250262889363
36.4314995,99.7514266967773,5.72969842229622E-4,0.0200339105674693
36.8293953,99.7514266967773,5.66509740613486E-4,0.0198080328885834
37.22369195,99.7514266967773,5.60483214528692E-4,0.0195973151933109
37.62328915,99.7514266967773,5.54514871683426E-4,0.0193886318770429
38.0495949,99.7514266967773,5.48229675752162E-4,0.0191688697815441
38.4834156,99.7514266967773,5.42085252229147E-4,0.0189540297982219
38.88146405,99.7514266967773,5.36401384673372E-4,0.0187552931703976
39.27362065,99.7514266967773,5.30863328728582E-4,0.0185616548506497
39.66708945,99.7514266967773,5.25870073708919E-4,0.0183870655142979
40.0692272,99.7514266967773,5.20662173372251E-4,0.0182049710969319
40.46416665,99.7514266967773,5.15278775409484E-4,0.018016740398933
40.8649292,99.7514266967773,5.1031690996515E-4,0.0178432486001801
41.2901096,99.7514266967773,5.05108109173409E-4,0.0176611226983709
41.71538545,99.7514266967773,4.99752124686513E-4,0.0174738505135144
42.11662865,99.7514266967773,4.95239214467866E-4,0.0173160564499254
42.50626375,99.7514266967773,4.90695840181695E-4,0.0171571972091502
42.9129028,99.7514266967773,4.8606030471818E-4,0.0169951155495867
43.30439375,99.7514266967773,4.81672134656461E-4,0.0168416830299462
43.69329455,99.7514266967773,4.77173640862811E-4,0.0166843930371612
44.09846305,99.7514266967773,4.73079138269525E-4,0.0165412286108226
44.49710275,99.7514266967773,4.68844126505726E-4,0.016393151276424
44.89287755,99.7514266967773,4.64750071392525E-4,0.0162500024962421
45.28173065,99.7514266967773,4.60441265315632E-4,0.016099344941106
45.68252945,99.7514266967773,4.56967643727059E-4,0.0159778896408063
46.072403,99.7514266967773,4.52949512669712E-4,0.015837395547892
46.47236635,99.7514266967773,4.49131884766375E-4,0.0157039120547684
46.87021445,99.7514266967773,4.45436902610332E-4,0.0155747168744871
47.26194955,99.7514266967773,4.417863618878E-4,0.0154470755904825
47.65686035,99.7514266967773,4.3794498295176E-4,0.0153127616416699
48.0540619,99.7514266967773,4.34793761709494E-4,0.0152025790807515
48.4831905,99.7514266967773,4.31205572033169E-4,0.0150771179032577
48.8791809,99.7514266967773,4.27369399831146E-4,0.014942986008082
49.2743111,99.7514266967773,4.2400334133687E-4,0.0148252916551353
49.6729126,99.7514266967773,4.20755605073178E-4,0.0147117344431181
50.0641365,99.7514266967773,4.17637946352503E-4,0.0146027253969407
50.4603195,99.7514266967773,4.14417789692817E-4,0.0144901325067419
50.85269165,99.7514266967773,4.1122174261235E-4,0.0143783826088234
51.25122455,99.7514266967773,4.08235226194083E-4,0.0142739589578351
51.64536475,99.7514266967773,4.05057080891286E-4,0.0141628349961988
52.0443859,99.7514266967773,4.02150371004455E-4,0.0140612017833726
52.43600275,99.7514266967773,3.99005037589295E-4,0.0139512250905348
52.83403015,99.7514266967773,3.96342403043708E-4,0.0138581259805492
53.23047065,99.7514266967773,3.93650051688983E-4,0.0137639878212931
53.62788585,99.7514266967773,3.90774451744131E-4,0.0136634423686759
54.0151958,99.7514266967773,3.87790282513732E-4,0.0135591007871934
54.4099827,99.7514266967773,3.85154256306869E-4,0.0134669320387017
54.8081398,99.7514266967773,3.82417939079095E-4,0.0133712566111572
55.2009258,99.7514266967773,3.79843093864618E-4,0.0132812270582034
55.5918579,99.7514266967773,3.77332651804257E-4,0.0131934493637852
55.99853515,99.7514266967773,3.74686514925528E-4,0.0131009270952982
56.3873634,99.7514266967773,3.72094991114489E-4,0.0130103143746325
56.7884827,99.7514266967773,3.69382669954896E-4,0.0129154779704509
57.1767139,99.7514266967773,3.67139761045146E-4,0.0128370545819981
57.5755577,99.7514266967773,3.6458715457413E-4,0.0127478026074871
58.0064945,99.7514266967773,3.61867391499437E-4,0.0126527059964838
58.3889999,99.7514266967773,3.59414610731857E-4,0.0125669444311838
58.7827148,99.7514266967773,3.57139483874643E-4,0.0124873945410714
59.1864948,99.7514266967773,3.54922036945996E-4,0.0124098614316782
59.58519935,99.7514266967773,3.52590234494373E-4,0.0123283298774256
59.9802151,99.7514266967773,3.50604258064447E-4,0.0122588901421135
60.35915755,99.7514266967773,3.48219991934984E-4,0.0121755241935309
60.766037,99.7514266967773,3.46302431296182E-4,0.0121084766187476
61.16246985,99.7514266967773,3.44130070389606E-4,0.0120325199436925
61.5511055,99.7514266967773,3.41832779018072E-4,0.011952195070562
62.0289154,99.7514266967773,3.39332454209687E-4,0.0118647711262128
62.4417763,99.7514266967773,3.37231861430895E-4,0.0117913238262551
62.839159,99.7514266967773,3.35098075267075E-4,0.0117167159184292
63.2332039,99.7514266967773,3.33155381807058E-4,0.0116487895736734
63.62974545,99.7514266967773,3.31147626176831E-4,0.0115785883278612
64.02112965,99.7514266967773,3.29234544095271E-4,0.0115116973459885
64.4183693,99.7514266967773,3.27311014831024E-4,0.0114444410780078
64.8131409,99.7514266967773,3.25287805870016E-4,0.0113736995059446
65.2165985,99.7514266967773,3.23574685841136E-4,0.0113138002042355
65.60590745,99.7514266967773,3.21617497372972E-4,0.011245367041013
66.00261305,99.7514266967773,3.19878405396609E-4,0.0111845596292521
66.3976898,99.7514266967773,3.17712281015615E-4,0.011108821014532
66.82032015,99.7514266967773,3.16031525608954E-4,0.0110500533429704
67.22265625,99.7514266967773,3.14321027911514E-4,0.0109902457311718
67.6157341,99.7514266967773,3.12679043636652E-4,0.0109328336935892
68.00814055,99.7514266967773,3.10718438678495E-4,0.0108642810726746
68.40755845,99.7514266967773,3.09158322573329E-4,0.010809731558508
68.80251695,99.7514266967773,3.07355294096838E-4,0.0107466886047845
69.19903185,99.7514266967773,3.05680007491968E-4,0.0106881121500688
69.5916672,99.7514266967773,3.03955157871942E-4,0.0106278027227952
69.98713685,99.7514266967773,3.02299574727701E-4,0.0105699152002693
70.38298415,99.7514266967773,3.00550656799868E-4,0.0105087642237716
70.7787285,99.7514266967773,2.99119957318826E-4,0.0104587397663925
71.2055817,99.7514266967773,2.97340711895059E-4,0.0103965283879391
71.6020279,99.7514266967773,2.95731689888304E-4,0.0103402688772134
71.9910469,99.7514266967773,2.94234798241581E-4,0.0102879300084469
72.3892937,99.7514266967773,2.92830209274713E-4,0.0102388185061088
72.781044,99.7514266967773,2.91187492388541E-4,0.0101813808527462
73.1776619,99.7514266967773,2.89584156397239E-4,0.0101253201537496
73.5746994,99.7514266967773,2.88207999326514E-4,0.0100772027736543
73.9686966,99.7514266967773,2.86982772804694E-4,0.0100343626854788
74.3636818,99.7514266967773,2.85410505822518E-4,0.00997938831547266
74.7627983,99.7514266967773,2.83706848910105E-4,0.00991981989196172
75.1544647,99.7514266967773,2.82560593973715E-4,0.00987974104803199
75.54584885,99.7514266967773,2.8089252316411E-4,0.00982141689385
75.9423447,99.7514266967773,2.79488472756057E-4,0.00977232422223975
76.3374405,99.7514266967773,2.78196365971198E-4,0.0097271456633286
76.73421095,99.7514266967773,2.76905563222759E-4,0.00968201270009647
77.1321259,99.7514266967773,2.75533187555903E-4,0.00963402753691968
77.5240021,99.7514266967773,2.74170328799417E-4,0.00958637513284675
77.9220085,99.7514266967773,2.73010899686798E-4,0.00954583565338455
78.30260085,99.7514266967773,2.71665215955702E-4,0.0094987837746749
78.7093544,99.7514266967773,2.70296347796198E-4,0.00945092125161532
79.09825135,99.7514266967773,2.68806800158725E-4,0.00939883916638899
79.50118255,99.7514266967773,2.67962440700408E-4,0.00936931610840588
79.8874702,99.7514266967773,2.66186895823615E-4,0.00930723411970682
80.2926941,99.7514266967773,2.65260266177664E-4,0.0092748344817365
80.7205238,99.7514266967773,2.63937228861017E-4,0.0092285744356999
81.101223,99.7514266967773,2.6273846879418E-4,0.00918665974804825
81.50004195,99.7514266967773,2.61516854072055E-4,0.00914394594657535
81.90776445,99.7514266967773,2.60080316915151E-4,0.00909371737465563
82.29335785,99.7514266967773,2.58896343589895E-4,0.00905231970594038
82.69060895,99.7514266967773,2.57572579553946E-4,0.00900603425013797
83.09708025,99.7514266967773,2.56735799007317E-4,0.00897677618906703
83.48022465,99.7514266967773,2.55447087293288E-4,0.00893171633892616
83.87596515,99.7514266967773,2.54183290037527E-4,0.00888752762368975
84.27466585,99.7514266967773,2.53304982558162E-4,0.00885681757196371
84.6677933,99.7514266967773,2.5204301569133E-4,0.00881269285634021
85.06912615,99.7514266967773,2.50885639177507E-4,0.00877222514606668
85.46108245,99.7514266967773,2.49764729064744E-4,0.00873303248478126
85.860199,99.7514266967773,2.48420217584777E-4,0.00868602159387332
86.2509651,99.7514266967773,2.47680250688684E-4,0.00866014862547846
86.6462059,99.7514266967773,2.4649883681337E-4,0.00861884044801993
87.04932405,99.7514266967773,2.45498372354506E-4,0.00858385917323447
87.4456749,99.7514266967773,2.44488801405153E-4,0.00854855948969067
87.8416672,99.7514266967773,2.43270612936296E-4,0.00850596548728307
88.2358818,99.7514266967773,2.42312375591355E-4,0.00847246068501241
88.63328935,99.7514266967773,2.41475601424854E-4,0.00844320284702287
89.02890015,99.7514266967773,2.40266806895273E-4,0.00840093730403053
89.4261818,99.7514266967773,2.39188455719396E-4,0.0083632327174614
89.8241577,99.7514266967773,2.38099007834163E-4,0.00832514013406164
90.21594235,99.7514266967773,2.3738363539428E-4,0.00830012711168811
90.6135826,99.7514266967773,2.36260117684902E-4,0.00826084327569587
91.01005175,99.7514266967773,2.35428759125127E-4,0.00823177479458486
91.4071274,99.7514266967773,2.34399189401165E-4,0.00819577585318759
91.8046341,99.7514266967773,2.33030612930302E-4,0.00814792352903154
92.19692615,99.7514266967773,2.32220210804695E-4,0.00811958779037395
92.5982895,99.7514266967773,2.31188007247168E-4,0.00808349675689399
92.9968376,99.7514266967773,2.30580036249515E-4,0.00806223902970332
93.37950515,99.7514266967773,2.29538667616049E-4,0.00802582753902269
93.7796097,99.7514266967773,2.28367653570344E-4,0.00798488299197007
94.1802063,99.7514266967773,2.27770449240033E-4,0.00796400172167948
94.60889435,99.7514266967773,2.26579270132564E-4,0.0079223521025372
95.0009842,99.7514266967773,2.25840082093013E-4,0.00789650636688857
95.3973007,99.7514266967773,2.24686653237173E-4,0.00785617668661444
95.79395295,99.7514266967773,2.24074397405543E-4,0.00783476914005395
96.1922646,99.7514266967773,2.22894791787077E-4,0.00779352418835934
96.5866165,99.7514266967773,2.22058899740899E-4,0.00776429719373773
96.9817543,99.7514266967773,2.21258470735486E-4,0.00773631016557643
97.3773842,99.7514266967773,2.20256289391194E-4,0.00770126885983196
97.7742043,99.7514266967773,2.19460116546073E-4,0.00767343064846409
98.17214965,99.7514266967773,2.1868260408661E-4,0.00764624489813322
98.5654335,99.7514266967773,2.17915972518301E-4,0.00761943959854199
98.9575691,99.7514266967773,2.17019249235458E-4,0.00758808563760343
99.346447,99.7514266967773,2.16037009731172E-4,0.00755374159899203
99.75681305,99.7514266967773,2.15428772601554E-4,0.0075324745664879
100.1555405,99.7514266967773,2.14692791036899E-4,0.00750674094534612
100.5509758,99.7514266967773,2.13794046203945E-4,0.00747531630083724
100.94122315,99.7514266967773,2.12922254515228E-4,0.00744483407395902
101.33387375,99.7514266967773,2.12227255096877E-4,0.0074205333949957
101.7382011,99.7514266967773,2.11436126099831E-4,0.00739287154195213
102.1405411,99.7514266967773,2.10379649210532E-4,0.00735593179057804
102.52965545,99.7514266967773,2.09845929145978E-4,0.00733727024985937
102.93292995,99.7514266967773,2.08949014041776E-4,0.00730590958188028
103.33245085,99.7514266967773,2.08082385443058E-4,0.00727560788262441
103.7218933,99.7514266967773,2.07238085988714E-4,0.00724608692268231
104.12690735,99.7514266967773,2.06692836115238E-4,0.00722702224179154
104.52721405,99.7514266967773,2.05882485223281E-4,0.00719868829452032
104.91918565,99.7514266967773,2.0518714233051E-4,0.00717437560596189
105.3152924,99.7514266967773,2.04525095738152E-4,0.00715122712371161
105.71660995,99.7514266967773,2.03619929542083E-4,0.00711957795601689
106.14871595,99.7514266967773,2.02785411296222E-4,0.0070903989963714
106.58423995,99.7514266967773,2.02029556610058E-4,0.00706397051084119
106.98305895,99.7514266967773,2.01587458329264E-4,0.00704851252899525
107.3807831,99.7514266967773,2.00595955187342E-4,0.00701384458697
107.7792244,99.7514266967773,1.996651969328E-4,0.00698130059205594
108.17542265,99.7514266967773,1.99448093881952E-4,0.00697370957629203
108.6105156,99.7514266967773,1.9845668411204E-4,0.00693904489902238
109.0248909,99.7514266967773,1.97556022387641E-4,0.0069075532303371
109.40490725,99.7514266967773,1.96719583542112E-4,0.00687830711685706
109.805645,99.7514266967773,1.9619200546916E-4,0.00685986033108951
110.2092438,99.7514266967773,1.95422070412295E-4,0.00683293952490542
110.6094437,99.7514266967773,1.95099826824642E-4,0.00682167226659588
111.0019226,99.7514266967773,1.9416563073391E-4,0.00678900806761923
111.4020729,99.7514266967773,1.93439583776554E-4,0.00676362181036902
111.8014488,99.7514266967773,1.92958775833064E-4,0.00674681034381343
112.1990166,99.7514266967773,1.92473057277798E-4,0.00672982717754538
112.5946236,99.7514266967773,1.91688458729342E-4,0.0067023936618651
112.9898529,99.7514266967773,1.91087684910778E-4,0.00668138758429294
113.396698,99.7514266967773,1.90626683730377E-4,0.00666526866190129
113.796772,99.7514266967773,1.8984171808295E-4,0.00663782231059266
114.19649885,99.7514266967773,1.89185974330523E-4,0.00661489420736095
114.59929275,99.7514266967773,1.88242350830466E-4,0.00658190037868762
114.9925652,99.7514266967773,1.87810278675523E-4,0.00656679296068262
115.4271927,99.7514266967773,1.87149685981782E-4,0.00654369531404832
115.82410815,99.7514266967773,1.86403931534398E-4,0.00651761998372021
116.22342685,99.7514266967773,1.85928491240831E-4,0.00650099619723185
116.65274425,99.7514266967773,1.85088561377985E-4,0.00647162802020926
117.05418775,99.7514266967773,1.845217213031E-4,0.00645180843717133
117.45104985,99.7514266967773,1.83895812535015E-4,0.00642992351521031
117.85250095,99.7514266967773,1.83476895229934E-4,0.0064152760569907
118.2471504,99.7514266967773,1.82436549590025E-4,0.00637890033531556
118.64676285,99.7514266967773,1.82064365415888E-4,0.00636588690265343
119.0446434,99.7514266967773,1.81780068657416E-4,0.006355946456553
119.44046785,99.7514266967773,1.8077595537756E-4,0.00632083760061398
119.84044265,99.7514266967773,1.80192678623925E-4,0.00630044330852885
120.2396393,99.7514266967773,1.79668477268105E-4,0.00628211458979388
120.63957975,99.7514266967773,1.79249249216236E-4,0.00626745626630196
121.0423317,99.7514266967773,1.78583818295648E-4,0.00624418945089678
121.43800355,99.7514266967773,1.77958320101732E-4,0.00622231888467594
121.905014,99.7514266967773,1.77320371117863E-4,0.00620001297614906
122.30326845,99.7514266967773,1.76717571613288E-4,0.00617893607039468
122.70196535,99.7514266967773,1.76315848848392E-4,0.00616488981987385
123.0992508,99.7514266967773,1.7581409273656E-4,0.00614734589987972
123.5044861,99.7514266967773,1.75117479503276E-4,0.00612298879382084
123.8984871,99.7514266967773,1.74594228273616E-4,0.00610469329628028
124.29470065,99.7514266967773,1.74009068006542E-4,0.00608423314708189
124.6916008,99.7514266967773,1.7350858954467E-4,0.00606673390016329
125.0941544,99.7514266967773,1.73143624864583E-4,0.00605397289736304
125.49156185,99.7514266967773,1.72331360257007E-4,0.00602557203695829
125.8972206,99.7514266967773,1.71951128721006E-4,0.0060122772280072
126.28957365,99.7514266967773,1.71521294376014E-4,0.00599724805510538
126.68603515,99.7514266967773,1.70813792980989E-4,0.00597251024409052
127.18641285,99.7514266967773,1.70020057958209E-4,0.00594475727126605
127.58192825,99.7514266967773,1.69783659517988E-4,0.00593649159153804
127.9908142,99.7514266967773,1.69204528518506E-4,0.00591624225589182
128.38008115,99.7514266967773,1.68637714054358E-4,0.0058964235683342
128.78204345,99.7514266967773,1.68151310736214E-4,0.00587941645930818
129.1870575,99.7514266967773,1.6746964444558E-4,0.00585558197362168
129.6171875,99.7514266967773,1.66891646749397E-4,0.00583537226396493
130.02401735,99.7514266967773,1.66411652182487E-4,0.00581858923714989
130.4195099,99.7514266967773,1.66089682151998E-4,0.00580733154377615
130.8474121,99.7514266967773,1.65540850797174E-4,0.00578814163626483
131.252182,99.7514266967773,1.65149935846946E-4,0.00577447328136175
131.64945225,99.7514266967773,1.64485194459221E-4,0.00575123057549724
132.04852295,99.7514266967773,1.64068081225918E-4,0.00573664619671042
132.4551544,99.7514266967773,1.63662677971311E-4,0.00572247125773814
132.8517914,99.7514266967773,1.6287573849654E-4,0.00569495589148741
133.2558136,99.7514266967773,1.62753825286442E-4,0.00569069319183364
133.65065765,99.7514266967773,1.6201049222196E-4,0.00566470252524336
134.05381775,99.7514266967773,1.61504109140371E-4,0.0056469968230899
134.42411805,99.7514266967773,1.61081669083898E-4,0.00563222619174468
134.82475285,99.7514266967773,1.60737348088243E-4,0.00562018699609241
135.23023985,99.7514266967773,1.60344937943817E-4,0.00560646636167192
135.6220474,99.7514266967773,1.59879736820791E-4,0.00559020058813954
136.02565005,99.7514266967773,1.59348941627672E-4,0.00557164131565287
136.43058015,99.7514266967773,1.59215024323033E-4,0.00556695889241374
136.82486725,99.7514266967773,1.58287397552867E-4,0.00553452438996039
137.2255707,99.7514266967773,1.5823858961139E-4,0.00553281781858007
137.6269455,99.7514266967773,1.576191732143E-4,0.0055111599025979
138.0280838,99.7514266967773,1.57003540717406E-4,0.00548963429081839
138.46065525,99.7514266967773,1.56639067718809E-4,0.00547689047967864
138.8526001,99.7514266967773,1.56270229451514E-4,0.00546399403676622
139.2640152,99.7514266967773,1.55809675814925E-4,0.00544789076275962
139.6615982,99.7514266967773,1.55254276824587E-4,0.0054284712176429
140.06607055,99.7514266967773,1.54953014210431E-4,0.00541793755980528
140.45718385,99.7514266967773,1.54359178878517E-4,0.00539717408666143
140.84916685,99.7514266967773,1.539614066603E-4,0.00538326596714336
141.2603531,99.7514266967773,1.53614302843197E-4,0.00537112947004185
141.6578903,99.7514266967773,1.53258476096572E-4,0.00535868797540462
142.06131745,99.7514266967773,1.52719198753195E-4,0.00533983212423758
142.4642944,99.7514266967773,1.52474235016566E-4,0.00533126695862119
142.859581,99.7514266967773,1.51723586372775E-4,0.00530502050254458
143.2592545,99.7514266967773,1.51460579080561E-4,0.00529582444337626
143.6649246,99.7514266967773,1.50916690876862E-4,0.00527680737331685
144.06092835,99.7514266967773,1.50383472654096E-4,0.00525816337951385
144.45740505,99.7514266967773,1.50293827536576E-4,0.00525502893484532
144.8562851,99.7514266967773,1.49609140656036E-4,0.00523108883412713
145.25540165,99.7514266967773,1.49254851347866E-4,0.00521870109607923
145.66719055,99.7514266967773,1.49053716369621E-4,0.0052116684045322
146.06477355,99.7514266967773,1.48485748371631E-4,0.00519180938362346
146.4953003,99.7514266967773,1.48159326549578E-4,0.00518039603320203
146.89815525,99.7514266967773,1.48040283874083E-4,0.00517623370189101
147.28684995,99.7514266967773,1.47454013463658E-4,0.00515573473649154
147.6989212,99.7514266967773,1.46831164225027E-4,0.00513395679108486
148.0885239,99.7514266967773,1.46698369879283E-4,0.00512931363214276
148.48916625,99.7514266967773,1.46146352433621E-4,0.00511001232285388
148.90098575,99.7514266967773,1.45899970481583E-4,0.00510139756928612
149.3008804,99.7514266967773,1.45394855190102E-4,0.00508373619545811
149.69327545,99.7514266967773,1.4503035265592E-4,0.00507099135160559
150.08907315,99.7514266967773,1.44649637964806E-4,0.00505767964911909
150.49871065,99.7514266967773,1.44158455589419E-4,0.00504050544018948
150.9005432,99.7514266967773,1.43779607474313E-4,0.00502725900259836
151.2951126,99.7514266967773,1.43311405510583E-4,0.00501088830456584
151.6983185,99.7514266967773,1.43061606722068E-4,0.00500215408119119
152.08316805,99.7514266967773,1.42591128809841E-4,0.0049857038045399
152.48474125,99.7514266967773,1.42506952619968E-4,0.00498276058111776
152.87747955,99.7514266967773,1.42020021946908E-4,0.00496573503310867
153.2842102,99.7514266967773,1.41749347224074E-4,0.00495627088196063
153.6802063,99.7514266967773,1.41126304805704E-4,0.00493448618201762
154.0734787,99.7514266967773,1.40854183139866E-4,0.00492497143845685
154.4775467,99.7514266967773,1.40433467504599E-4,0.00491026110155941
154.8816528,99.7514266967773,1.40083994325129E-4,0.00489804175961989
155.27752685,99.7514266967773,1.39824786502517E-4,0.00488897854903906
155.7079926,99.7514266967773,1.3932561289001E-4,0.00487152492622413
156.10785675,99.7514266967773,1.38910458222642E-4,0.00485700902876371
156.49921415,99.7514266967773,1.38879200756252E-4,0.00485591611035846
156.9064331,99.7514266967773,1.38614518817577E-4,0.00484666149711808
157.3052139,99.7514266967773,1.37795717649426E-4,0.00481803208564427
157.7014008,99.7514266967773,1.37780000023191E-4,0.00481748251829339
158.1005554,99.7514266967773,1.37313728278911E-4,0.00480117931045143
158.4961319,99.7514266967773,1.36940430099259E-4,0.00478812692654752
158.90274045,99.7514266967773,1.36505807701719E-4,0.00477293033922094
159.2980347,99.7514266967773,1.36353828927462E-4,0.0047676163960651
159.6938553,99.7514266967773,1.35831778938942E-4,0.00474936289996301
160.1219864,99.7514266967773,1.35261945943349E-4,0.00472943866934787
160.55852505,99.7514266967773,1.35107096132969E-4,0.0047240243403136
160.95763395,99.7514266967773,1.3475572846347E-4,0.00471173875746398
161.35818485,99.7514266967773,1.3459719069153E-4,0.00470619547872483
161.758522,99.7514266967773,1.34312960282775E-4,0.00469625735254458
162.1534653,99.7514266967773,1.33625479944806E-4,0.00467221957848972
162.55156705,99.7514266967773,1.33669012238591E-4,0.00467374168666402
162.945961,99.7514266967773,1.33061733358871E-4,0.00465250815940108
163.3508606,99.7514266967773,1.32770346456156E-4,0.0046423198061593
163.7479858,99.7514266967773,1.3288935554052E-4,0.00464648096295525
164.18196105,99.7514266967773,1.32175590836934E-4,0.00462152415513755
164.57850645,99.7514266967773,1.31755335037371E-4,0.00460682989641157
164.97613525,99.7514266967773,1.31477723282622E-4,0.00459712319170007
165.3825531,99.7514266967773,1.3144477233961E-4,0.00459597106082552
165.7775421,99.7514266967773,1.30855719577534E-4,0.00457537481040329
166.1721802,99.7514266967773,1.30600148358589E-4,0.00456643875379682
166.57200625,99.7514266967773,1.30362034186616E-4,0.00455811308344811
166.97369385,99.7514266967773,1.29702907724495E-4,0.00453506670365367
167.3769836,99.7514266967773,1.29674855596561E-4,0.00453408586001961
167.771965,99.7514266967773,1.29334399353915E-4,0.00452218179559143
168.16164395,99.7514266967773,1.28825172373575E-4,0.0045043766564187
168.5963974,99.7514266967773,1.28568691390457E-4,0.00449540878987612
168.99810795,99.7514266967773,1.28343175405304E-4,0.00448752361557007
169.4025116,99.7514266967773,1.28051579148167E-4,0.0044773279422436
169.80229185,99.7514266967773,1.28057986381642E-4,0.00447755197138608
170.1876526,99.7514266967773,1.27485960179286E-4,0.00445755105521979
170.5885239,99.7514266967773,1.27135184418017E-4,0.00444528616846213
170.99573515,99.7514266967773,1.27029395671789E-4,0.00444158726125136
171.38854215,99.7514266967773,1.26343098033326E-4,0.00441759084032608
171.774765,99.7514266967773,1.26534911141603E-4,0.00442429759236374
172.18395995,99.7514266967773,1.26082850641834E-4,0.00440849128118301
172.58096315,99.7514266967773,1.25788204673702E-4,0.00439818897460496
172.9919128,99.7514266967773,1.25307845863895E-4,0.0043813932120243
173.3770981,99.7514266967773,1.2533112024902E-4,0.00438220700171399
173.78408815,99.7514266967773,1.24473112539986E-4,0.00435220673216734
174.17588805,99.7514266967773,1.24831015397768E-4,0.00436472081810377
174.5702591,99.7514266967773,1.24392090631339E-4,0.00434937379829857
174.96766665,99.7514266967773,1.24216291415809E-4,0.00434322697258073
175.3664169,99.7514266967773,1.23664275986037E-4,0.00432392573377752
175.7719803,99.7514266967773,1.23516026654526E-4,0.00431874219071769
176.16484835,99.7514266967773,1.23330563163316E-4,0.0043122574532628
176.5716705,99.7514266967773,1.22937949822827E-4,0.00429852971408486
176.9684296,99.7514266967773,1.22600079090096E-4,0.00428671605210126
177.41428375,99.7514266967773,1.22229276659095E-4,0.00427375093213619
177.79542545,99.7514266967773,1.22022413218292E-4,0.00426651794469553
178.19195555,99.7514266967773,1.21943162559123E-4,0.00426374694262668
178.5907364,99.7514266967773,1.2146047777401E-4,0.00424686985223811
178.9886093,99.7514266967773,1.21139314231256E-4,0.00423564035773622
179.3913269,99.7514266967773,1.21025912475112E-4,0.00423167526136755
179.79453275,99.7514266967773,1.20719271834602E-4,0.00422095356065042
180.1910782,99.7514266967773,1.20611235820418E-4,0.00421717607763699
180.5873184,99.7514266967773,1.20046353782958E-4,0.00419742495744608
180.9899521,99.7514266967773,1.19949015833946E-4,0.00419402153265545
181.3926239,99.7514266967773,1.1965743150796E-4,0.0041838262765021
181.78188325,99.7514266967773,1.19383611974382E-4,0.00417425216693643
182.18208315,99.7514266967773,1.19322435035835E-4,0.00417211311314108
182.5832596,99.7514266967773,1.18732269950315E-4,0.00415147797029073
182.98115535,99.7514266967773,1.1852493522462E-4,0.00414422850435734
183.3798141,99.7514266967773,1.18231963292285E-4,0.00413398473049948
183.7832031,99.7514266967773,1.17597212408948E-4,0.00411179064366951
184.18856045,99.7514266967773,1.18011802532952E-4,0.00412628680185147
184.5786667,99.7514266967773,1.17577743025756E-4,0.00411110989600545
184.9830475,99.7514266967773,1.17076841950852E-4,0.00409359587240741
185.38032535,99.7514266967773,1.17170127574019E-4,0.00409685760748318
185.77361295,99.7514266967773,1.16573030984279E-4,0.00407598010434542
186.1750946,99.7514266967773,1.16188881977282E-4,0.00406254832088399
186.57427975,99.7514266967773,1.16544110584324E-4,0.00407496890154979
186.97573855,99.7514266967773,1.16054569887714E-4,0.00405785209397601
187.3725281,99.7514266967773,1.15936280016399E-4,0.00405371608448948
187.79814915,99.7514266967773,1.15477717493661E-4,0.00403768242984829
188.20040895,99.7514266967773,1.15278905610191E-4,0.00403073096539129
188.60105895,99.7514266967773,1.14877837593896E-4,0.00401670760817818
189.00154115,99.7514266967773,1.1467439637955E-4,0.00400959427900524
189.3990555,99.7514266967773,1.14461045337887E-4,0.00400213445237367
189.8048477,99.7514266967773,1.14089223492059E-4,0.00398913368853353
190.2008438,99.7514266967773,1.14156004871388E-4,0.00399146870179678
190.6015091,99.7514266967773,1.13668293519289E-4,0.0039744158573178
190.98473355,99.7514266967773,1.13544350841295E-4,0.00397008219724808
191.39913175,99.7514266967773,1.13231219284851E-4,0.00395913354142836
191.8266296,99.7514266967773,1.13135621801745E-4,0.00395579097208899
192.2295456,99.7514266967773,1.13009893922327E-4,0.00395139489238906
192.62970735,99.7514266967773,1.1249389822023E-4,0.00393335308462343
193.02560425,99.7514266967773,1.12414444706344E-4,0.00393057498973231
193.4303436,99.7514266967773,1.12088691177375E-4,0.00391918500620192
193.8179016,99.7514266967773,1.11902628677348E-4,0.0039126793243828
194.22084045,99.7514266967773,1.1157400195034E-4,0.00390118887938252
194.6132889,99.7514266967773,1.11437106618193E-4,0.00389640232930745
195.02320095,99.7514266967773,1.11351425975055E-4,0.0038934065026243
195.47798155,99.7514266967773,1.10787184400418E-4,0.00387367777623839
195.8765793,99.7514266967773,1.10572022539285E-4,0.00386615463424073
196.27303315,99.7514266967773,1.10548982015319E-4,0.00386534902151465
196.67957305,99.7514266967773,1.10372636023831E-4,0.00385918307775633
197.078949,99.7514266967773,1.09791069519941E-4,0.00383884858461332
197.46726225,99.7514266967773,1.09540233397495E-4,0.0038300780908215
197.8705292,99.7514266967773,1.10010372096862E-4,0.00384651650688329
198.26799775,99.7514266967773,1.09317793488544E-4,0.00382230047162741
198.69522095,99.7514266967773,1.09220386273957E-4,0.00381889462496353
199.0941315,99.7514266967773,1.0900888313189E-4,0.00381149941020595
199.4975128,99.7514266967773,1.08691654663918E-4,0.0038004075057314
199.90016935,99.7514266967773,1.08474675120052E-4,0.00379282080839343
200.30056,99.7514266967773,1.08496160349976E-4,0.00379357204020895
200.7021408,99.7514266967773,1.07895700033103E-4,0.00377257692423437
201.10456085,99.7514266967773,1.07714542671759E-4,0.0037662427507608
201.536438,99.7514266967773,1.07580021324801E-4,0.00376153920716087
201.93476105,99.7514266967773,1.07500914404457E-4,0.00375877323092507
202.3295212,99.7514266967773,1.06855295317599E-4,0.00373619913697899
202.72938535,99.7514266967773,1.07040006477201E-4,0.0037426575691329
203.1298904,99.7514266967773,1.07105643317241E-4,0.0037449525635399
203.55919645,99.7514266967773,1.06561492140631E-4,0.00372592629862346
203.96398925,99.7514266967773,1.06546641011956E-4,0.00372540702839007
204.35178375,99.7514266967773,1.06157430710932E-4,0.00371179827660601
204.7481766,99.7514266967773,1.05937691798141E-4,0.0037041150978371
205.15103145,99.7514266967773,1.05676441880111E-4,0.00369498048531857
205.5527725,99.7514266967773,1.06000807122767E-4,0.00370632192736948
205.95471195,99.7514266967773,1.05624638457631E-4,0.00369316917684024
206.3453827,99.7514266967773,1.04976665755592E-4,0.00367051278865706
206.75035095,99.7514266967773,1.05178965424771E-4,0.00367758620366332
207.1492004,99.7514266967773,1.048554139786E-4,0.00366627321603496
207.58013155,99.7514266967773,1.04601057952755E-4,0.00365737964869773
207.9810104,99.7514266967773,1.04380344514249E-4,0.00364966239560311
208.3813858,99.7514266967773,1.038795524843E-4,0.00363215218476574
208.7791519,99.7514266967773,1.04313480208815E-4,0.0036473244828257
209.181427,99.7514266967773,1.03946497498191E-4,0.00363449291951717
209.5823059,99.7514266967773,1.03408575825352E-4,0.0036156844694179
210.0101013,99.7514266967773,1.03671999992695E-4,0.00362489510463969
210.41256715,99.7514266967773,1.03071518315612E-4,0.00360389924180462
210.81368255,99.7514266967773,1.03169873435681E-4,0.00360733823201682
211.21166995,99.7514266967773,1.02800366660948E-4,0.00359441841471846
211.6095581,99.7514266967773,1.02579753211184E-4,0.00358670465773371
212.00917815,99.7514266967773,1.02615014846722E-4,0.00358793758205322
212.39619445,99.7514266967773,1.02160349252178E-4,0.00357204018364259
212.84205625,99.7514266967773,1.02053505892293E-4,0.00356830440182843
213.24124145,99.7514266967773,1.02056045890625E-4,0.00356839321295892
213.62779995,99.7514266967773,1.01508438761896E-4,0.0035492461105558
214.03891755,99.7514266967773,1.01113450748927E-4,0.00353543534087157
214.44742585,99.7514266967773,1.01143598904746E-4,0.00353648947219392
214.8434448,99.7514266967773,1.00979171289455E-4,0.00353074025487605
215.24032595,99.7514266967773,1.00780972320559E-4,0.00352381022099857
215.62026975,99.7514266967773,1.00409303273022E-4,0.00351081479975601
216.03463745,99.7514266967773,1.00644885754805E-4,0.00351905194946871
216.43505855,99.7514266967773,1.00100308414313E-4,0.00350001078371724
216.87140655,99.7514266967773,9.99950964341998E-5,0.00349633204315384
217.29402925,99.7514266967773,9.97115821315933E-5,0.00348641895565011
217.68681335,99.7514266967773,9.96772867114681E-5,0.0034852198150863
218.12904355,99.7514266967773,9.92637341969882E-5,0.00347075993695763
218.5153885,99.7514266967773,9.9062207592841E-5,0.00346371355219724
218.9257965,99.7514266967773,9.91130747117704E-5,0.00346549212278917
219.3159256,99.7514266967773,9.8690954736644E-5,0.00345073268309944
219.72229,99.7514266967773,9.86773951341146E-5,0.00345025857112289
220.115448,99.7514266967773,9.8725801202281E-5,0.00345195109098885
220.51862335,99.7514266967773,9.81467577942544E-5,0.00343170481798092
220.92095185,99.7514266967773,9.86107803850447E-5,0.00344792938409247
221.3268585,99.7514266967773,9.76710672442906E-5,0.0034150722812689
221.71287535,99.7514266967773,9.79485033425009E-5,0.00342477284414339
222.1201706,99.7514266967773,9.7389110324596E-5,0.00340521364771315
222.5150375,99.7514266967773,9.72981212191736E-5,0.00340203221046062
222.91197965,99.7514266967773,9.69410777830962E-5,0.00338954817423413
223.3182144,99.7514266967773,9.71687478926646E-5,0.00339750866757568
223.7111206,99.7514266967773,9.6982349040876E-5,0.00339099122520545
224.1115036,99.7514266967773,9.66219252957765E-5,0.00337838899635582
224.50778965,99.7514266967773,9.64985397194542E-5,0.00337407481536553
224.91309355,99.7514266967773,9.62032375261563E-5,0.00336374956385162
225.3166733,99.7514266967773,9.6109773872396E-5,0.00336048160392993
225.70986935,99.7514266967773,9.62280041454311E-5,0.00336461552956053
226.1140518,99.7514266967773,9.57285967747615E-5,0.00334715373338327
226.51029965,99.7514266967773,9.53787399323342E-5,0.00333492097665504
226.9139023,99.7514266967773,9.53386418425653E-5,0.00333351894554424
227.3144455,99.7514266967773,9.54318585994055E-5,0.00333677827270649
227.71233365,99.7514266967773,9.53562523692856E-5,0.00333413469822677
228.11221315,99.7514266967773,9.53313831353603E-5,0.00333326514459302
228.5115738,99.7514266967773,9.4831307118654E-5,0.00331577996918371
228.9125824,99.7514266967773,9.47274228052129E-5,0.00331214765053192
229.3089371,99.7514266967773,9.45663003637245E-5,0.00330651399873163
229.7093811,99.7514266967773,9.42980884474548E-5,0.00329713595970122
230.1035309,99.7514266967773,9.42215499810124E-5,0.00329445978954589
230.50634,99.7514266967773,9.39273456308853E-5,0.00328417292415683
230.90247345,99.7514266967773,9.36196343045392E-5,0.003273413786872
231.30004885,99.7514266967773,9.3488034774985E-5,0.00326881240471976
231.70120235,99.7514266967773,9.33377081548304E-5,0.00326355622918987
232.13076785,99.7514266967773,9.31301670455549E-5,0.00325629954704737
232.52975465,99.7514266967773,9.30375817252619E-5,0.00325306229808608
232.9330215,99.7514266967773,9.27237184763992E-5,0.00324208805861536
233.32971955,99.7514266967773,9.3045773726773E-5,0.00325334873170535
233.733902,99.7514266967773,9.25362399375226E-5,0.00323553286494834
234.1301193,99.7514266967773,9.23550997983565E-5,0.00322919929364883
234.5290985,99.7514266967773,9.21419965724909E-5,0.00322174813190528
234.9281082,99.7514266967773,9.2034406120464E-5,0.00321798622798825
235.32458495,99.7514266967773,9.23350691450686E-5,0.00322849892115624
235.724144,99.7514266967773,9.19494624209312E-5,0.00321501616856403
236.13033295,99.7514266967773,9.18505232335433E-5,0.0032115567564176
236.52651215,99.7514266967773,9.14784547015602E-5,0.00319854736718742
236.92584225,99.7514266967773,9.14935976127417E-5,0.00319907683960635
237.3159256,99.7514266967773,9.10145483162878E-5,0.00318232686420587
237.7165375,99.7514266967773,9.12604042462232E-5,0.00319092322539242
238.11250305,99.7514266967773,9.08922606603715E-5,0.00317805107204096
238.5049591,99.7514266967773,9.06625908205501E-5,0.00317002065806119
238.8933258,99.7514266967773,9.05161748444484E-5,0.00316490121833736
239.3034439,99.7514266967773,9.050821903798E-5,0.00316462304328601
239.73210905,99.7514266967773,9.04951674811857E-5,0.00316416669514635
240.11267855,99.7514266967773,9.0227080430351E-5,0.00315479302204025
240.5157547,99.7514266967773,8.99997689298196E-5,0.00314684506747621
240.911293,99.7514266967773,8.99433189947906E-5,0.00314487129352415
241.29576875,99.7514266967773,8.94706002659572E-5,0.00312834266664186
241.6860733,99.7514266967773,8.9249323210771E-5,0.00312060570667031
242.07775115,99.7514266967773,8.92870341442641E-5,0.00312192427077847
242.46957395,99.7514266967773,8.93289939075207E-5,0.00312339139536786
242.8717651,99.7514266967773,8.9075879079022E-5,0.00311454122653923
243.27394105,99.7514266967773,8.89032930992867E-5,0.00310850675172331
243.6822281,99.7514266967773,8.87488262242173E-5,0.00310310581203557
244.07098385,99.7514266967773,8.85218766946456E-5,0.0030951705137988
244.47802735,99.7514266967773,8.82717497827919E-5,0.00308642481758014
244.87104795,99.7514266967773,8.83491004513974E-5,0.0030891293864125
245.2705765,99.7514266967773,8.81512807239444E-5,0.00308221261272533
245.6678467,99.7514266967773,8.80050843487193E-5,0.00307710085135382
246.06384275,99.7514266967773,8.74751756093634E-5,0.00305857257375396
246.46759035,99.7514266967773,8.78471583701505E-5,0.00307157896399128
246.8598404,99.7514266967773,8.74058492315295E-5,0.003056148574529
247.25078585,99.7514266967773,8.73885385917028E-5,0.0030555433074022
247.64858245,99.7514266967773,8.7348232278795E-5,0.00305413399576206
248.04396055,99.7514266967773,8.72055564976965E-5,0.00304914533208729
248.445755,99.7514266967773,8.7400354300616E-5,0.00305595644407748
248.84346005,99.7514266967773,8.70728322692211E-5,0.00304450462479794
249.23664855,99.7514266967773,8.68447320667115E-5,0.00303652909324166
249.6366806,99.7514266967773,8.67697594113542E-5,0.00303390767172567
250.07059475,99.7514266967773,8.64963015336426E-5,0.00302434620747002
250.47818755,99.7514266967773,8.62810354451575E-5,0.00301681942115935
250.8729324,99.7514266967773,8.659699056694E-5,0.00302786680303986
251.2741852,99.7514266967773,8.62616085925708E-5,0.0030161401605794
251.688118,99.7514266967773,8.58054917441599E-5,0.00300019201902657
252.08998105,99.7514266967773,8.57457533245361E-5,0.00299810326309567
252.49235535,99.7514266967773,8.57712631802136E-5,0.00299899521609138
252.8903046,99.7514266967773,8.57509397034704E-5,0.00299828460501645
253.2874603,99.7514266967773,8.53792418554809E-5,0.00298528817676507
253.6855316,99.7514266967773,8.5292510866686E-5,0.0029822556247093
254.0878296,99.7514266967773,8.52978022941524E-5,0.00298244063965568
254.48291015,99.7514266967773,8.52091075829795E-5,0.0029793394259783
254.8759308,99.7514266967773,8.49444702774567E-5,0.00297008637333765
255.28369905,99.7514266967773,8.51622583776534E-5,0.00297770134187599
255.6765213,99.7514266967773,8.4933890372813E-5,0.00296971644660185
256.07901005,99.7514266967773,8.44635762022964E-5,0.00295327189518519
256.47384645,99.7514266967773,8.46900140875626E-5,0.00296118930376093
256.87561035,99.7514266967773,8.42451345538555E-5,0.00294563407530963
257.2691193,99.7514266967773,8.38845061735084E-5,0.00293302469138141
257.6662445,99.7514266967773,8.40167279555401E-5,0.00293764783061329
258.06752015,99.7514266967773,8.40405948196292E-5,0.00293848233635067
258.46080015,99.7514266967773,8.39271621330701E-5,0.00293451615849895
258.84814455,99.7514266967773,8.36326136251009E-5,0.00292421725961891
259.26226805,99.7514266967773,8.3509381040101E-5,0.00291990842797556
259.6638794,99.7514266967773,8.36329813678023E-5,0.00292423011775532
260.0992279,99.7514266967773,8.344216919666E-5,0.00291755836351958
260.5041199,99.7514266967773,8.34113746584324E-5,0.00291648163141372
260.8950958,99.7514266967773,8.31163168317777E-5,0.00290616492418803
261.2898865,99.7514266967773,8.3150261337853E-5,0.00290735179502983
261.7034149,99.7514266967773,8.28325407881446E-5,0.00289624268490016
262.1031799,99.7514266967773,8.25230312004547E-5,0.00288542067134457
262.4890747,99.7514266967773,8.25141387123308E-5,0.00288510974518639
262.8966064,99.7514266967773,8.25701773327892E-5,0.00288706913751011
263.30099485,99.7514266967773,8.22157744029622E-5,0.002874677426677
263.6875,99.7514266967773,8.23452894058724E-5,0.00287920592328225
264.08540345,99.7514266967773,8.23350001609282E-5,0.00287884615947301
264.4871063,99.7514266967773,8.22004510347742E-5,0.00287414164457252
264.88980105,99.7514266967773,8.16444001665155E-5,0.00285469930652152
265.28997805,99.7514266967773,8.16347562404315E-5,0.00285436210630879
265.6858368,99.7514266967773,8.18543888953708E-5,0.00286204156976821
266.08932495,99.7514266967773,8.12109251531245E-5,0.00283954283752184
266.4868774,99.7514266967773,8.11739852395373E-5,0.00283825123215165
266.87887575,99.7514266967773,8.11429120960085E-5,0.0028371647586017
267.27978515,99.7514266967773,8.11906188608451E-5,0.00283883282730228
267.67770385,99.7514266967773,8.08255277866524E-5,0.00282606740512771
268.0922394,99.7514266967773,8.08230342067835E-5,0.0028259802170204
268.4828033,99.7514266967773,8.07014375572891E-5,0.0028217285859192
268.8787689,99.7514266967773,8.05874990531832E-5,0.00281774472213927
269.1901398,99.7514266967773,8.02012703766309E-5,0.00280424022295912
269.27716065,99.7514266967773,8.02499414722148E-5,0.002805942009518
269.33113095,99.7514266967773,8.01296186163333E-5,0.00280173491665501
269.6287384,99.7514266967773,8.00741844669446E-5,0.00279979665968338