File: M16M2-MH3.csv
Magnetic Field (Oe),Temperature (K),Moment (emu),M (emu/g)
-0.341258779168129,3.007444,5.75599971948283E-5,0.00201258731450449
990.439727783203,3.00705455,0.059356005314811,2.07538480121717
1542.3359375,3.0061896,0.0999130819794164,3.4934644048747
2396.42321777344,3.00261625,0.159558094137796,5.57895434048238
3103.76184082031,3.0046823,0.203492476661005,7.1151215615736
3780.77795410156,3.0047817,0.240293185546237,8.40185963448381
4461.37109375,3.00394965,0.286649766998796,10.022719125832
5071.21240234375,3.00415325,0.319205173479667,11.1610200517366
5736.28247070313,3.0028486,0.355146032889323,12.4176934576686
6411.42504882813,3.002844,0.383637228519966,13.4138891090897
7051.6611328125,3.0031338,0.41481775035464,14.5041171452671
7761.47143554687,3.00160195,0.443466431057369,15.5058192677402
8586.35498046875,3.0043817,0.469724743268661,16.4239420723308
9232.08056640625,3.003046,0.494045975539268,17.2743348090653
9896.61181640625,3.0014749,0.513312703276147,17.9479966180471
10481.8032226562,3.0022975,0.53366813884309,18.6597251343738
11151.5517578125,3.0025029,0.552459297676979,19.3167586600342
11921.689453125,3.0006833,0.569780919504957,19.9224097729006
12571.4365234375,3.0030807,0.583351361426517,20.3969007491789
13176.623046875,3.00254585,0.598055271104274,20.9110234651844
13886.974609375,3.0044622,0.609534626434698,21.3123995256887
14521.51953125,3.0039787,0.622023292906687,21.7490661855485
15091.7861328125,3.0016849,0.632218554320748,22.1055438573688
15741.5625,3.00357475,0.642795638200096,22.4753719650383
16421.94140625,3.0038967,0.651474482478884,22.7788280587022
17047.93359375,3.00281035,0.660882950939809,23.1077954874059
17793.3291015625,3.0021484,0.669591145540032,23.412277816085
18379.12890625,3.0033168,0.676535058755595,23.6550719844614
19184.9072265625,3.004084,0.684202082697608,23.9231497446716
19775.0810546875,3.00424085,0.691314543101267,24.171837171373
20430.9345703125,3.0037577,0.698111361886951,24.4094881778654
21146.2294921875,3.00468125,0.704275775824171,24.6250271267193
21781.927734375,3.00534895,0.709483183951612,24.8071043339724
22493.08984375,3.0050689,0.715053248128917,25.0018618226894
23133.623046875,3.00508225,0.719651537169569,25.1626411597751
23904.060546875,3.00609055,0.725269493573579,25.3590732018734
24574.5478515625,3.0068009,0.730101142158848,25.5280119635961
25315.302734375,3.007056,0.734687717289851,25.6883817234214
26051.326171875,3.006933,0.739037843870339,25.8404840514104
26762.3037109375,3.0061095,0.743256692554568,25.9879962431667
27367.70703125,3.0069324,0.747180212785901,26.1251822652413
28003.3583984375,3.0072329,0.750362398109043,26.2364474863302
28674.0078125,3.0068884,0.754015567726962,26.3641806897539
29289.3837890625,3.005927,0.756981322467849,26.4678784079667
29975.2724609375,3.00719165,0.760401785625669,26.5874750218765
30601.15234375,3.00692265,0.763187032476447,26.6848612754002
31296.9677734375,3.00748645,0.766301399412281,26.7937552242056
31937.48828125,3.0066297,0.76938424305058,26.9015469598105
32623.1181640625,3.0067832,0.771845791861239,26.9876151000433
33248.310546875,3.0064955,0.774733139213523,27.0885713011721
33874.033203125,3.00770915,0.77708676208746,27.1708658072538
34584.724609375,3.0083311,0.779757910567681,27.2642626072616
35225.33984375,3.00816595,0.781923167038596,27.3399708754754
35975.8828125,3.007144,0.784500070322322,27.4300723888924
36581.8671875,3.00799275,0.786876377115762,27.5131600390127
37302.3046875,3.0086646,0.789208085765553,27.5946883134809
37997.546875,3.00929645,0.791539569084831,27.6762087092598
38703.232421875,3.0072767,0.793817127726113,27.7558436267872
39404.265625,3.0085356,0.795957052491835,27.8306661710432
40009.8671875,3.0089208,0.797755481243925,27.8935482952421
40690.6015625,3.00856915,0.799857251031986,27.9670367493701
41306.0859375,3.0099392,0.801544997151734,28.0260488514592
42086.5859375,3.0098188,0.803580046211598,28.0972044129929
42762.197265625,3.0100176,0.805508124212355,28.1646197277047
43413.005859375,3.0090349,0.807449487668192,28.2324995688179
44109.234375,3.00969765,0.809277799598209,28.2964265593779
44714.404296875,3.0081228,0.810837858687409,28.3509740799793
45425.427734375,3.0089834,0.812679712342615,28.4153745574341
46060.658203125,3.0098174,0.814405109564257,28.4757031316174
46806.09765625,3.01018465,0.816111760593996,28.5353762445453
47381.9140625,3.0090623,0.817636209720915,28.5886786615704
48107.951171875,3.009277,0.819244403909377,28.6449092276006
48788.546875,3.01050405,0.820852810826582,28.7011472316987
49454.021484375,3.00839005,0.822567609588524,28.761105230368
50124.59765625,3.01114925,0.823788433927278,28.8037913960587
50800.236328125,3.0096744,0.825304536783957,28.856801985453
51480.78515625,3.0093869,0.82688289932411,28.911989486857
52116.5,3.00928845,0.828238792388638,28.9593983352671
52867.318359375,3.0080202,0.82965633880103,29.0089628951409
53447.76171875,3.0101438,0.83119416518362,29.0627330483783
54098.298828125,3.0100154,0.832441114568546,29.1063326772219
54779.29296875,3.01004945,0.833773753083988,29.1529284295101
55439.552734375,3.01192675,0.835165421568796,29.2015881667411
56214.96875,3.0108578,0.83655876846523,29.2503065896934
56905.708984375,3.0087128,0.837910005820477,29.2975526510656
57596.505859375,3.0088692,0.838999699247355,29.3356538198376
58332.39453125,3.0098755,0.840525300633994,29.3889965256641
59057.927734375,3.010772,0.841857640338697,29.4355818300244
59643.130859375,3.0093298,0.843124078759597,29.4798628936922
60338.701171875,3.01061985,0.844381249833098,29.5238199242342
60989.654296875,3.0092205,0.845430542848179,29.5605084911951
61640.578125,3.01063915,0.846622603583938,29.6021889365013
62331.646484375,3.0099536,0.847742137290746,29.6413334717044
62929.623046875,3.0099479,0.848795183583032,29.678153272134
63638.236328125,3.00986455,0.84992135607639,29.7175299327409
64337.080078125,3.0094447,0.851180559129347,29.7615580115156
65040.853515625,3.00930835,0.852276121915078,29.7998644026251
65654.01171875,3.01058315,0.853297514405545,29.8355774267673
66307.578125,3.009212,0.854429561594136,29.8751594962985
66991.24609375,3.009323,0.855530165215943,29.9136421404176
67760.515625,3.01060975,0.856678479195715,29.9537929788712
68459.125,3.0086603,0.857753151023227,29.991368916896
69027.2109375,3.0088763,0.85870929686094,30.0248005895434
69736.1015625,3.00911425,0.859728192876808,30.0604263243639
70460.1640625,3.00874115,0.860869345716006,30.1003267732869
71198.76953125,3.0095867,0.861910559229884,30.1367328402057
71766.6015625,3.0090095,0.862802386863514,30.1679156245984
72415.37109375,3.0089818,0.863835360430141,30.2040335814735
73138.95703125,3.0091951,0.864750736235007,30.2360397284968
73727.4140625,3.00910725,0.865730296262092,30.2702900790941
74481.44140625,3.0094377,0.866726923286502,30.3051371778497
75159.9921875,3.00918855,0.867758915046776,30.3412208058313
75853.36328125,3.0090672,0.868874390910832,30.3802234584207
76602.6015625,3.00982345,0.869809073984019,30.4129046847559
77175.609375,3.00976885,0.870597840430351,30.4404839311312
77829.04296875,3.0095522,0.871525957346095,30.4729355715418
78452.93359375,3.00921715,0.872434357620962,30.5046978189148
79186.47265625,3.0085059,0.87328386362786,30.534400826149
79915.6953125,3.0083439,0.874278849572365,30.5691905444883
80619.59375,3.0094924,0.875187450517237,30.600959808295
81182.25,3.0102422,0.875904496507407,30.6260313464128
81946.3671875,3.0094352,0.876870683910622,30.659814122749
82534.94921875,3.00820875,0.877660933059889,30.6874452118842
83188.37109375,3.00949765,0.878542494472152,30.7182690374878
83891.5078125,3.0093427,0.8793254981264,30.7456467876364
84570.35546875,3.0090458,0.880183566079801,30.7756491636294
85269.4609375,3.0091496,0.881081863086543,30.8070581498791
85832.5390625,3.00786735,0.881856158303739,30.8341314092216
86495.23828125,3.00798145,0.882743812261223,30.8651682608819
87235.015625,3.0064218,0.883588810837528,30.8947136656478
87903.48828125,3.0092323,0.884273153206274,30.9186417204991
88506.375,3.00733375,0.885091986389195,30.9472722513705
89225.15234375,3.0064144,0.885918072936964,30.9761563963973
89813.3828125,3.0075182,0.886649319314806,31.0017244515666
89692.4921875,3.0059193,0.886588896228517,30.9996117562419
88988.71875,3.00530815,0.885789583314829,30.9716637522668
88326.5703125,3.00680025,0.884905880949185,30.9407650681533
87519.35546875,3.0057465,0.884092194273567,30.9123144850898
86926.57421875,3.00566955,0.88313496249866,30.8788448426105
86263.9453125,3.0055112,0.882354266907868,30.8515477939814
85646.02734375,3.0046054,0.881559069889537,30.8237437024314
84933.2578125,3.004272,0.88079487061944,30.7970234482322
84236.14453125,3.00315235,0.879876442192824,30.7649105661827
83603.38671875,3.0036976,0.879091814237297,30.7374760222831
82965.68359375,3.0036751,0.878152782548869,30.704642746464
82342.40234375,3.00258875,0.877266472040724,30.6736528685568
81699.67578125,3.00265835,0.876531168810813,30.647942965413
80957.40234375,3.00181365,0.875625139445695,30.6162636169824
80364.57421875,3.00257695,0.874830139425328,30.588466413473
79656.890625,3.0023775,0.873874474701592,30.5550515629927
79064.30078125,3.00089585,0.872914328508219,30.5214800177699
78361.59375,3.0015184,0.871989049308917,30.4891275982139
77578.82421875,3.0014546,0.870989768818938,30.4541877209419
76966.109375,3.0013361,0.869998182248591,30.4195168618389
76303.56640625,2.999529,0.869217932503325,30.3922354022142
75660.421875,3.00049365,0.868139622467363,30.3545322541036
74997.98046875,3.0003717,0.867346232806538,30.326791356872
74275.5546875,3.0003481,0.866339360440567,30.2915860293905
73582.85546875,3.0001078,0.865302959212381,30.2553482242091
73039.8046875,2.9985732,0.864414978444377,30.2242999456076
72327.40625,2.999053,0.863397926711005,30.188738696189
71564.984375,2.9995401,0.862333195974097,30.1515103487447
70877.55859375,2.99830805,0.861314635933775,30.1158963613208
70204.984375,2.9983549,0.860179358183881,30.0762013351007
69607.25390625,2.99683795,0.859193134743635,30.0417179980292
68964.4296875,2.9974185,0.858209920905844,30.0073398918127
68331.9765625,2.99725695,0.857239476809491,29.9734082800521
67559.2421875,2.9965641,0.856075535054069,29.9327110158765
66901.94921875,2.9970915,0.855047040767924,29.8967496772001
66323.97265625,2.99662855,0.854036853090232,29.8614284297284
65621.49609375,2.9962399,0.852920105670553,29.8223813171522
64913.58203125,2.996472,0.851752623301451,29.7815602552955
64216.046875,2.9951324,0.850563101693677,29.739968590688
63633.1484375,2.99458335,0.849442476022658,29.7007858749181
62900.791015625,2.9964383,0.848376387938531,29.6635100677808
62322.767578125,2.9952694,0.847171496427858,29.6213809939811
61645.001953125,2.9947653,0.846145294383869,29.5854998036318
60992.3515625,2.9951379,0.84481773995075,29.5390818164598
60299.546875,2.994519,0.84376102796325,29.5021338448689
59671.658203125,2.9954319,0.84253399564644,29.4592306170084
58964.515625,2.9940877,0.841242696345307,29.414080291794
58336.662109375,2.99494245,0.839921285566171,29.3678771176983
57574.232421875,2.9954479,0.838560823660932,29.320308519613
56892.046875,2.9924512,0.837298750342568,29.276180081908
56263.943359375,2.9940351,0.836095693444246,29.2341151553932
55526.341796875,2.9939364,0.834657855628252,29.1838411058829
54953.380859375,2.99319205,0.833372187559793,29.1388876769158
54300.66015625,2.9933362,0.832158878281379,29.0964642755727
53538.560546875,2.9929042,0.830730290940469,29.0465136692472
52975.671875,2.99340585,0.829281879616701,28.9958699166679
52223.36328125,2.991281,0.828078592189077,28.953796929688
51520.71484375,2.9913313,0.826320778123362,28.8923348994183
50907.892578125,2.9927703,0.825036504829934,28.8474302388089
50284.919921875,2.99254345,0.823609312506572,28.7975284093207
49577.755859375,2.993014,0.821848810870975,28.7359724080761
48909.74609375,2.9921384,0.820644901281801,28.6938776671958
48267.080078125,2.9932456,0.818895981605289,28.6327266295556
47554.279296875,2.9916196,0.817242538251629,28.5749139248821
46901.42578125,2.99311855,0.815790148971623,28.5241310829239
46258.66796875,2.99063385,0.814138017835411,28.4663642599794
45456.65625,2.99153375,0.812096990345455,28.3949996624285
44774.29296875,2.990217,0.810672868367404,28.3452051876715
44166.36328125,2.9908644,0.80875488657707,28.2781428873101
43488.849609375,2.99099125,0.806921199639272,28.2140279594151
42810.673828125,2.99058165,0.805068237064646,28.1492390582044
42137.787109375,2.9920306,0.803321810265585,28.0881751841114
41455.298828125,2.98972295,0.801380960702603,28.0203133112798
40837.404296875,2.99102185,0.799712723603806,27.9619833427904
40174.810546875,2.99006795,0.79762471579875,27.8889760768794
39442.62109375,2.9896368,0.795525370521478,27.8155723958559
38774.73828125,2.98968315,0.793479876031714,27.7440516095005
38091.916015625,2.99070515,0.791107049960326,27.6610856629484
37484.197265625,2.99059785,0.789243708670853,27.5959338696102
36806.578125,2.99044285,0.786924872807448,27.5148556925681
36158.888671875,2.98925635,0.784812353102818,27.4409913672314
35516.248046875,2.98968865,0.782408820385977,27.3569517617474
34853.69140625,2.99093975,0.779866143883866,27.2680469889464
34110.67578125,2.989398,0.777688698303831,27.191912528106
33528.013671875,2.99082005,0.774934498159258,27.0956118237503
32810.705078125,2.9909129,0.772561864313143,27.0126525983616
32217.75390625,2.9897046,0.769713329648619,26.9130534842174
31475.142578125,2.9901283,0.766806197098898,26.8114054929685
30811.9814453125,2.9886124,0.76418724149057,26.7198336185514
30247.9453125,2.9903084,0.760965211775332,26.6071752368997
29518.234375,2.9899068,0.758182561107489,26.5098797590031
28924.1201171875,2.9882704,0.754806541396941,26.3918371117811
28174.888671875,2.9883091,0.751291736840435,26.2689418475677
27530.630859375,2.99025035,0.747521443216103,26.1371133991644
26846.6796875,2.9894216,0.743710576650654,26.0038663164564
26207.71875,2.9902389,0.740234327807303,25.8823191541015
25453.28125,2.990772,0.735376068320413,25.7124499412732
24749.1171875,2.9898292,0.730985903058448,25.5589476593863
24109.7734375,2.99075305,0.727019976567746,25.4202789009701
23325.896484375,2.98733,0.722197628881422,25.2516653455043
22661.5927734375,2.9902177,0.717019599146851,25.070615354785
21987.4814453125,2.9898126,0.711600864709637,24.8811491157216
21373.0888671875,2.99000835,0.705847158139283,24.6799705643106
20739.09765625,2.98923445,0.700653983234712,24.4983910221927
20044.6982421875,2.98972405,0.694216632961905,24.2733088448218
19245.56640625,2.9895829,0.686330670749566,23.9975759003345
18641.72265625,2.99083015,0.679997343229593,23.7761308821536
17927.8603515625,2.9899507,0.672184234853704,23.502945274605
17268.068359375,2.9901557,0.663807729027841,23.2100604555189
16644.228515625,2.9894538,0.65613142567097,22.9416582402437
15855.0014648438,2.9889275,0.646542416506084,22.6063781995134
15176.326171875,2.98948655,0.634641562978421,22.1902644398049
14506.8364257813,2.9896333,0.62497791243342,21.8523745606091
13832.876953125,2.9899964,0.612718758711747,21.4237328220891
13103.7646484375,2.9912755,0.599449812125119,20.9597836407384
12464.1044921875,2.99052355,0.585021534165961,20.4552983974112
11834.9262695313,2.990854,0.571615124731306,19.9865428227729
11130.6674804688,2.9912102,0.554677897985413,19.3943320973921
10476.7705078125,2.9919772,0.536088664716272,18.7443589061634
9692.861328125,2.9907062,0.515927707960919,18.0394303482839
9098.24853515625,2.9911443,0.493811000893565,17.2661189123624
8348.857421875,2.993046,0.469634856750722,16.4207991870882
7699.51708984375,2.99347865,0.442943354712888,15.487529885066
7064.98901367187,2.9938574,0.418628391219142,14.6373563363336
6340.27880859375,2.9936998,0.38784957107395,13.5611738137745
5626.1357421875,2.9944141,0.354391797182537,12.391321579809
4900.87231445313,2.9931414,0.318583509028718,11.1392835324727
4291.1201171875,2.99402895,0.280117938892777,9.79433352771948
3586.28930664063,2.99393325,0.239141747691672,8.36159956963888
2830.98803710938,2.9944286,0.195995720047997,6.85299720447542
2215.99597167969,2.9948282,0.150804274298921,5.2728767237385
1525.71215820313,2.99459205,0.104098656544824,3.63981316590294
729.833343505859,2.9947783,0.0562185931480795,1.96568507510768
-244.44751739502,2.99741995,-0.0131200320154483,-0.458742378162528
-897.613616943359,2.9962935,-0.054473897155075,-1.90468171870892
-1553.61883544922,2.9953752,-0.101908833640362,-3.56324593148119
-2448.77502441406,2.9958918,-0.161130068461735,-5.63391847768304
-3033.54809570313,2.99607385,-0.199290179546764,-6.9681880960407
-3775.48852539063,2.9960141,-0.242103661243351,-8.46516298053675
-4381.40258789063,2.99672785,-0.282705564424045,-9.88480994489668
-5052.06030273438,2.9959837,-0.315434302266097,-11.0291714079055
-5847.3525390625,2.9970356,-0.356188942453596,-12.4541588270488
-6502.50024414062,2.9958541,-0.38468260503444,-13.4504407354699
-7127.42504882813,2.99637815,-0.415602557642533,-14.5315579595291
-7742.32666015625,2.99679255,-0.440169468713695,-15.3905408641152
-8537.4638671875,2.9970386,-0.470244006312064,-16.4420981227994
-9142.9306640625,2.99736785,-0.490902523446637,-17.1644238967356
-9852.6396484375,2.9967771,-0.513217381253324,-17.9446636801861
-10517.517578125,2.998515,-0.533416868468287,-18.6509394569331
-11137.5649414062,2.99889745,-0.549442012598565,-19.211259181768
-11832.4375,2.9988745,-0.566745778026635,-19.8162859449872
-12497.1533203125,2.99755025,-0.582668089084671,-20.3730101078556
-13157.1518554687,2.99829615,-0.595150829089037,-20.8094695485677
-13832.2143554687,2.99894905,-0.608636215709568,-21.2809865632716
-14676.8037109375,2.998559,-0.622835781207743,-21.7774748674036
-15271.8481445313,2.9997499,-0.634135895883269,-22.1725837721423
-16036.8959960938,2.9991131,-0.644686096691583,-22.5414719122931
-16692.8427734375,2.9999032,-0.654371586816023,-22.8801254131477
-17358.892578125,3.0005357,-0.663264409817662,-23.1910632803378
-18038.8525390625,3.0004834,-0.670556029813024,-23.4460150284274
-18769.30078125,3.000442,-0.678448370978098,-23.7219710132202
-19410.2529296875,2.9999297,-0.685806527618963,-23.9792492174463
-20035.66796875,2.99995735,-0.691820013159346,-24.1895109496275
-20756.068359375,3.00178945,-0.699148329997329,-24.4457458041024
-21522.1015625,3.0013478,-0.705276709627676,-24.6600248121565
-22242.7822265625,3.0010929,-0.71100509120071,-24.8603178741507
-22863.6220703125,3.00029375,-0.716454384541553,-25.050852606348
-23534.08203125,3.00225115,-0.720823752912014,-25.2036277241963
-24304.875,3.0029162,-0.726397613902505,-25.3985179686191
-24955.2314453125,3.00335445,-0.730357957493473,-25.5369915207508
-25675.826171875,3.0036471,-0.735391540401609,-25.7129909231332
-26467.1689453125,3.0030738,-0.738945454618565,-25.8372536579918
-27177.744140625,3.0038297,-0.74357642204013,-25.9991755958087
-27858.361328125,3.0026982,-0.747484076994898,-26.1358068879335
-28543.734375,3.00471735,-0.751066485688189,-26.2610659331535
-29149.48828125,3.0045115,-0.754048308513063,-26.3653254724847
-29889.80859375,3.0042007,-0.757397353631123,-26.4824249521372
-30575.50390625,3.0055397,-0.760605266143493,-26.594589725297
-31161.2431640625,3.0043796,-0.76382627487033,-26.7072124080535
-31851.8955078125,3.0045871,-0.766423013389229,-26.7980074611619
-32657.74609375,3.0054922,-0.769727924151422,-26.9135637815182
-33367.8671875,3.00696815,-0.772528536936872,-27.011487305485
-33928.44140625,3.0052637,-0.77488800970929,-27.0939863534717
-34693.998046875,3.0056717,-0.777559633782936,-27.1873997826201
-35264.701171875,3.00544585,-0.78004940871557,-27.2744548501948
-36075.0859375,3.0054436,-0.782547113417179,-27.3617871824188
-36791.212890625,3.0066607,-0.784934018323873,-27.4452453959396
-37421.6484375,3.00835465,-0.787300504005967,-27.5279896505583
-38091.724609375,3.0088801,-0.789565854999975,-27.6071977272718
-38897.501953125,3.00664,-0.791764926454849,-27.6840883375821
-39518.587890625,3.00790475,-0.793884017745344,-27.7581824386484
-40234.173828125,3.0093718,-0.79601814607502,-27.8328023103154
-40854.720703125,3.008615,-0.79809621270412,-27.9054619826615
-41520.03515625,3.0247178,-0.799610605926976,-27.9584127946495
-42255.89453125,3.0165136,-0.801713683277681,-28.0319469677511
-42966.435546875,3.0128802,-0.803678460009309,-28.1006454548709
-43647.380859375,3.0135963,-0.80584189224145,-28.1762899385122
-44342.8046875,3.01268645,-0.807406744853413,-28.2310050648046
-45013.453125,3.01209475,-0.809226302963836,-28.2946259777565
-45664.375,3.01191925,-0.810760731765821,-28.3482773344693
-46384.7734375,3.0109706,-0.812506340077361,-28.4093125901175
-46955.076171875,3.0109062,-0.813949267199743,-28.4597645874036
-47645.666015625,3.01080965,-0.815606097153264,-28.5176957046596
-48316.38671875,3.011999,-0.817290514312593,-28.5765914095312
-48971.796875,3.0104545,-0.818657330958562,-28.6243822013483
-49782.380859375,3.0112959,-0.820453269154311,-28.6871772431577
-50483.44140625,3.01173105,-0.822049733792569,-28.7429976850549
-51148.5625,3.0109379,-0.823556411757144,-28.7956787327673
-51724.091796875,3.0107185,-0.824807574990592,-28.8394256989717
-52509.8125,3.0123336,-0.826309771234728,-28.8919500431723
-53145.267578125,3.01094605,-0.82783248506876,-28.945191785621
-53861.052734375,3.0118077,-0.829257205771654,-28.9950071948131
-54466.58203125,3.0111505,-0.830432744274481,-29.0361099396672
-55142.236328125,3.01079115,-0.831842249630109,-29.0853933437101
-55887.474609375,3.01014195,-0.833229218121188,-29.1338887454961
-56543.736328125,3.01134765,-0.834597465898564,-29.1817295768729
-57284.23046875,3.011338,-0.835954364371681,-29.2291735794294
-57959.77734375,3.0107484,-0.837242446413452,-29.2742114130578
-58585.103515625,3.0105901,-0.838561492834035,-29.320331917274
-59251.03515625,3.0109391,-0.839662712565921,-29.3588361037035
-59941.5703125,3.0109551,-0.840959022842701,-29.4041616378567
-60687.48046875,3.0104203,-0.842177505922165,-29.4467659413344
-61258.279296875,3.01135635,-0.843291548952021,-29.4857184948259
-61984.021484375,3.0095744,-0.844659280650038,-29.5335412814699
-62676.22265625,3.01028965,-0.845855711749866,-29.5753745367086
-63435.31640625,3.010299,-0.84690584872204,-29.6120926126587
-64174.41015625,3.0099146,-0.848250360050392,-29.6591034982655
-64787.5546875,3.01002385,-0.849417187049953,-29.6999016451032
-65506.931640625,3.01085565,-0.850413066695605,-29.7347226117344
-66215.33984375,3.0105338,-0.851498511587188,-29.7726752303213
-66974.484375,3.0104866,-0.852809571252796,-29.8185164773705
-67668.05078125,3.0092468,-0.853952987816736,-29.8584960775082
-68326.29296875,3.00974425,-0.855056213981412,-29.8970704189305
-69060.234375,3.0105808,-0.855978131923604,-29.9293053120141
-69819.140625,3.0092003,-0.857191573205683,-29.97173332887
-70503.01953125,3.00959865,-0.858442176074075,-30.0154607018907
-71186.68359375,3.00986805,-0.859278344344889,-30.0446973547164
-71920.1875,3.0105882,-0.860277371645682,-30.0796283792197
-72629.375,3.0101166,-0.861303749730219,-30.1155157248328
-73217.671875,3.0100869,-0.86226536790685,-30.1491387380017
-73966.83984375,3.011801,-0.863297412587441,-30.1852242163441
-74580.0859375,3.0097444,-0.864309968088621,-30.2206282548469
-75273.3359375,3.0096626,-0.865110636240794,-30.248623644783
-75962.35546875,3.0081677,-0.866111390591852,-30.2836150556592
-76570.71484375,3.0097166,-0.86707484542955,-30.3173022877465
-77269.59765625,3.0099392,-0.867919324880372,-30.3468295412717
-77832.2265625,3.00952505,-0.868812257006417,-30.3780509442803
-78561.765625,3.00849975,-0.869850915922258,-30.4143676895894
-79310.9453125,3.0109603,-0.870673587890615,-30.4431324437278
-79914.015625,3.0089959,-0.871517334589339,-30.4726340765503
-80662.734375,3.0084075,-0.872603937833195,-30.5106271969649
-81301.19140625,3.00866415,-0.873368252237582,-30.5373514768385
-82020.0703125,3.0090469,-0.874340637979339,-30.5713509782986
-82814.67578125,3.0085545,-0.875209879427085,-30.6017440359121
-83407.578125,3.00886655,-0.876125930659347,-30.6337737992779
-84030.68359375,3.0078125,-0.876827898074789,-30.6583181145031
-84850.2265625,3.0091896,-0.877844710475938,-30.6938709956622
-85513.640625,3.0083028,-0.878563013089973,-30.7189864716774
-86081.45703125,3.0088549,-0.879359457856118,-30.7468341907734
-86860.8359375,3.0089951,-0.880274650241197,-30.7788339245174
-87519.36328125,3.0080161,-0.881063156756141,-30.8064040823825
-88137.43359375,3.00815555,-0.881952855847134,-30.8375124422075
-88851.35546875,3.00872615,-0.882751047890971,-30.8654212549291
-89514.796875,3.00767255,-0.883569669540649,-30.8940443895332
-89910.21875,3.00799105,-0.884155269969724,-30.9145199290113
-89213.33984375,3.0080705,-0.883346125447297,-30.8862281624929
-88575.69921875,3.0067233,-0.882544765187334,-30.8582085729837
-87967.88671875,3.0061531,-0.881640063591131,-30.8265756500396
-87245.79296875,3.005878,-0.880953223864476,-30.8025602749817
-86552.9921875,3.0047441,-0.879981142357603,-30.768571411105
-85800.75390625,3.0053284,-0.879119927152801,-30.7384589913567
-85103.25390625,3.0052316,-0.878261582328277,-30.7084469345551
-84460.68359375,3.0037662,-0.877327663531319,-30.675792431165
-83738.16796875,3.005625,-0.876612884631967,-30.6508001619569
-83060.94921875,3.0030367,-0.875741482875511,-30.6203315690738
-82423.15625,3.0037564,-0.874717641799074,-30.5845329300376
-81724.9765625,3.0024588,-0.873865593399334,-30.5547410279487
-81052.60546875,3.00241435,-0.872999589863138,-30.5244611840258
-80305.23828125,3.0020037,-0.872030099418604,-30.4905629167344
-79672.18359375,3.00204125,-0.871055217969743,-30.4564761527882
-79084.68359375,3.00247355,-0.870286914088811,-30.4296123807277
-78426.91015625,3.00178635,-0.869386548522904,-30.3981310672344
-77759.1328125,3.0012536,-0.868510269981597,-30.3674919573985
-77061.45703125,3.0021137,-0.867477272975004,-30.3313731809442
-76393.546875,3.0014622,-0.866528775886319,-30.2982089470741
-75661.32421875,2.9981167,-0.865586558212235,-30.2652642731551
-75078.296875,3.00116875,-0.864699264975046,-30.2342400340925
-74410.80078125,2.99902415,-0.863698977995271,-30.1992649648696
-73762.984375,2.99987445,-0.862848294299383,-30.1695207796987
-72980.32421875,2.998194,-0.861679815074126,-30.1286648627317
-72337.7109375,2.99800275,-0.860617159432628,-30.0915090710709
-71699.9453125,2.99915985,-0.859701568556403,-30.05949540407
-70987.4921875,2.99910435,-0.858630525805684,-30.0220463568421
-70329.87109375,2.9975941,-0.857610886808412,-29.9863946436508
-69717.17578125,2.9984871,-0.856623890361149,-29.9518842783619
-68979.53125,2.9978647,-0.855615351147146,-29.9166206694806
-68311.640625,2.9975127,-0.854669594882268,-29.8835522686108
-67744.01953125,2.9969565,-0.853615024748838,-29.8466791870223
-67056.484375,2.9970497,-0.852401472618562,-29.8042472943553
-66413.66796875,2.9965676,-0.851490104693512,-29.7723812829899
-65751.59765625,2.9975537,-0.850342146580119,-29.7322428874168
-65023.71484375,2.9965355,-0.849443196438827,-29.7008110642947
-64405.830078125,2.9964273,-0.848229441683047,-29.6583720868198
-63668.703125,2.9953423,-0.847031248206275,-29.6164772100096
-62980.92578125,2.9952974,-0.845824704386173,-29.5742903631529
-62328.30859375,2.9955504,-0.844779668034529,-29.5377506305779
-61740.4375,2.9947022,-0.843620455320686,-29.4972187175065
-61107.80859375,2.99614285,-0.84251695624725,-29.4586348338199
-60369.759765625,2.9958732,-0.841301924362626,-29.4161512014904
-59747.03125,2.9941585,-0.840070626174528,-29.3730988172912
-59044.666015625,2.9945756,-0.838722287757948,-29.3259541174108
-58402.044921875,2.994339,-0.837615345123757,-29.287249829502
-57774.07421875,2.99410235,-0.836353648997179,-29.2431345803209
-57051.806640625,2.9942417,-0.834996410763317,-29.1956786980181
-56429.03515625,2.994689,-0.83386918355958,-29.1562651594259
-55756.0234375,2.99380445,-0.832548539735528,-29.1100888019415
-55143.09765625,2.99420305,-0.83132227253071,-29.0672123262486
-54450.537109375,2.9939276,-0.829888060823299,-29.0170650637517
-53728.353515625,2.9931271,-0.828499312362604,-28.9685074252659
-53160.203125,2.9943044,-0.827259374594211,-28.9251529578395
-52472.5546875,2.992584,-0.825787835151908,-28.873700529787
-51755.1484375,2.9930758,-0.8243223073807,-28.8224583000245
-51152.546875,2.9928986,-0.823034760309278,-28.7774391716531
-50480.0234375,2.9927059,-0.821497118328418,-28.7236754660286
-49782.591796875,2.99291455,-0.819961721291674,-28.6699902549536
-49174.72265625,2.9921759,-0.818573333900457,-28.6214452412747
-48452.5,2.9914551,-0.817020549468577,-28.5671520793209
-47650.1640625,2.9924138,-0.815108006326919,-28.5002799415007
-46972.751953125,2.9915519,-0.813404474326573,-28.4407158855445
-46284.908203125,2.9915285,-0.811765188629022,-28.383398203812
-45672.36328125,2.99228765,-0.810307433763506,-28.3324277539687
-44999.8828125,2.9924057,-0.808521712093932,-28.2699899333543
-44362.357421875,2.9927293,-0.806988771070507,-28.2163905968709
-43575.2734375,2.9916039,-0.804888107689615,-28.1429408283082
-42941.748046875,2.9909601,-0.803007744935137,-28.0771938788509
-42329.20703125,2.99124635,-0.801437839144555,-28.0223020679914
-41606.75390625,2.9908409,-0.799442380680614,-27.9525307930285
-40904.443359375,2.99080215,-0.797442946343817,-27.8826205015321
-40296.41015625,2.9907166,-0.795773367995035,-27.82424363619
-39623.84375,2.99015475,-0.793641893196017,-27.7497165453153
-38891.318359375,2.9914298,-0.791439659467704,-27.6727153660036
-38208.759765625,2.99096535,-0.789322697791554,-27.5986957269774
-37621,2.99104395,-0.787292523788006,-27.5277106219582
-36868.595703125,2.99022795,-0.784732078194338,-27.4381845522496
-36111.423828125,2.99031815,-0.782381749781273,-27.3560052371074
-35438.900390625,2.99000335,-0.779894678906705,-27.2690447170177
-34796.138671875,2.99139985,-0.777369911081604,-27.1807661217344
-34113.43359375,2.9899397,-0.775113963414102,-27.1018868326609
-33485.60546875,2.98996125,-0.772470321496226,-27.0094518005673
-32813.1142578125,2.99115625,-0.769661749897156,-26.911249996404
-32130.62109375,2.99024735,-0.767258366486963,-26.8272156114323
-31458.166015625,2.99040535,-0.764262515898552,-26.7224655908585
-30820.4580078125,2.99028575,-0.761223297661265,-26.6161992189253
-30160.142578125,2.99083995,-0.758504295856184,-26.5211292257407
-29331.6044921875,2.9900193,-0.754780284729332,-26.3909190464801
-28747.5859375,2.99087595,-0.751759604533184,-26.2853008578036
-28123.3798828125,2.9895601,-0.748287826522824,-26.1639100182806
-27359.3232421875,2.9888728,-0.744609933126363,-26.0353123470756
-26750.52734375,2.9904488,-0.741271335469143,-25.9185781632567
-26131.140625,2.99037695,-0.737231333742206,-25.7773193616156
-25506.6220703125,2.9900373,-0.733595537470126,-25.6501936178366
-24797.4765625,2.99062135,-0.729214729038973,-25.4970184978662
-24172.9677734375,2.9901359,-0.725279153225644,-25.3594109519456
-23399.5830078125,2.9908071,-0.720372127102954,-25.1878366119914
-22705.1591796875,2.9879642,-0.715371019137084,-25.0129726971008
-22136.3349609375,2.9905131,-0.709928697757165,-24.822681739761
-21496.7451171875,2.9890658,-0.705144930190864,-24.6554171395407
-20817.84765625,2.98983455,-0.699021854913888,-24.4413235983877
-20163.51171875,2.98955765,-0.693661725567858,-24.2539064883866
-19554.5615234375,2.98981725,-0.687882830655197,-24.0518472257062
-18860.16015625,2.9901719,-0.680733626636929,-23.8018750572353
-18141.0615234375,2.9906087,-0.673114813263328,-23.5354829812352
-17417.130859375,2.989665,-0.665006139183567,-23.2519629085163
-16803.0087890625,2.99009395,-0.656265434559293,-22.9463438657095
-16173.9897460938,2.9900446,-0.64823159519234,-22.6654403913406
-15504.8779296875,2.98966575,-0.638149164116403,-22.3129078362379
-14855.5439453125,2.99059415,-0.627259138694303,-21.932137716584
-14141.6938476563,2.9893333,-0.615523227189706,-21.5217911604792
-13377.9453125,2.9910789,-0.602684508736515,-21.0728849208572
-12658.0947265625,2.990342,-0.588787200006326,-20.5869650351862
-12049.3530273437,2.99040615,-0.573645872623486,-20.0575479938282
-11410.2475585938,2.9910979,-0.559471259686366,-19.5619321568659
-10650.6484375,2.99052465,-0.541691507501059,-18.940262500037
-9986.74951171875,2.992691,-0.522081026886128,-18.2545813596548
-9367.93798828125,2.9910054,-0.504007096777804,-17.6226257614617
-8723.4345703125,2.99135195,-0.480954407415486,-16.8165876718701
-7983.64404296875,2.9937277,-0.455673425489454,-15.932637254876
-7399.2021484375,2.99218155,-0.432325413809358,-15.1162732101174
-6664.76684570312,2.99274625,-0.402831520868303,-14.0850182121784
-6100.46704101562,2.9932933,-0.375536086097244,-13.1306323810225
-5370.57299804687,2.9917579,-0.341370776056989,-11.9360411208737
-4651.0810546875,2.99428995,-0.304500093361965,-10.6468564112575
-4086.26806640625,2.9949238,-0.270899160033912,-9.47199860258434
-3300.87060546875,2.99490285,-0.223514281738711,-7.81518467617871
-2681.00207519531,2.99465375,-0.179736650092066,-6.28449825496734
-2005.96612548828,2.99572825,-0.140730915661468,-4.92066138676462
-1395.74829101562,2.99509595,-0.100573491160733,-3.51655563499066
-669.984222412109,2.9943731,-0.0527541395274388,-1.84455033312723
219.887153625488,2.99879695,0.00948904227244156,0.331784694840614
857.429290771484,2.99613025,0.0576003376816186,2.01399782103562
1528.83856201172,2.99634005,0.104836121395635,3.66559865019703
2199.9970703125,2.99592805,0.144387200876183,5.04850352713927
3043.48168945313,2.99600995,0.201807665695086,7.05621208724077
3705.38830566406,2.99652155,0.238400548904684,8.3356835281358
4431.69287109375,2.9958205,0.278998463244748,9.75519102254364
5031.9521484375,2.99565065,0.317119333873642,11.0880885969805
5712.291015625,2.9955678,0.347883572649237,12.1637612814419
6422.33154296875,2.99575445,0.381408516484687,13.3359621148492
7102.61328125,2.9964664,0.412329632173206,14.4171200060562
7717.67358398438,2.99652185,0.436971768550147,15.2787331660891
8387.1083984375,2.99702905,0.463424141823196,16.2036413224894
9008.14599609375,2.99595905,0.484587675647052,16.9436250226242
9773.09814453125,2.9979317,0.507171739683148,17.7332776112989
10483.1079101562,2.9970919,0.530584069313545,18.5518905354386
11063.0083007813,2.99861895,0.546730065127514,19.1164358436194
11727.6796875,2.99728295,0.561731636178079,19.6409662999328
12398.0180664062,2.9985039,0.577717097636122,20.1998985187455
13087.935546875,2.99820565,0.592561077247355,20.7189187848725
13737.9560546875,2.99835015,0.606102702228514,21.1924021758222
14443.0415039062,2.99902915,0.616803013412334,21.5665389305012
15067.8598632812,2.999045,0.6284633862476,21.9742442743916
15762.9404296875,2.9987323,0.637669427715137,22.2961338361936
16413.5239257813,2.9993657,0.649174040364556,22.6983930197397
17099.439453125,3.0012913,0.657030595027104,22.9730977282204
17845.2021484375,3.000761,0.665767163182647,23.2785721392534
18535.52734375,3.0010873,0.673740575589149,23.5573627828374
19115.9345703125,3.00160075,0.681316680093787,23.8222615417408
19756.974609375,3.0012187,0.687342677756733,24.0329607607249
20597.5322265625,3.0020156,0.694986263963748,24.3002190197115
21223.1220703125,3.0028844,0.700286453618616,24.4855403363152
21853.8642578125,3.00166605,0.706198770169103,24.6922646912274
22524.63671875,3.00290415,0.711732277433198,24.8857439661957
23124.7412109375,3.00273085,0.715451075392391,25.0157718668668
23790.6298828125,3.00287545,0.720522864737794,25.1931071586641
24426.2099609375,3.0035613,0.724709968143523,25.3395093756477
25176.896484375,3.005059,0.729297389708441,25.4999087310644
25842.6083984375,3.0024989,0.733640884041176,25.6517791622789
26443.7958984375,3.00431955,0.737806333465401,25.797424247042
27124.2197265625,3.0049536,0.741697600333413,25.9334825291403
27744.822265625,3.0042027,0.745019270997456,26.0496248600509
28535.3134765625,3.0032966,0.748718487890449,26.1789681080577
29145.7587890625,3.0049752,0.751668392844026,26.282111637903
29851.71484375,3.0048022,0.755024722652138,26.3994658269978
30582.630859375,3.00635,0.758708416984466,26.5282663281282
31253.5087890625,3.0060128,0.761483145243996,26.6252847987411
31868.6455078125,3.0053103,0.764492402008947,26.7305035667464
32549.978515625,3.00630065,0.767394086231249,26.8319610570367
33250.525390625,3.006153,0.770221727827347,26.9308296443128
33840.78125,3.0069543,0.77248294300477,27.0098931120549
34621.451171875,3.0060835,0.775182845861997,27.10429530986
35267.265625,3.0064921,0.777422596449781,27.1826082674749
35822.6328125,3.00701595,0.779507827387907,27.2555184401366
36613.330078125,3.0077543,0.782260815007705,27.3517767485211
37264.353515625,3.0066866,0.784662374833851,27.435747371813
37974.501953125,3.0066415,0.786959524076607,27.5160672754058
38630.048828125,3.009761,0.789086012351504,27.5904200122903
39296.05859375,3.0076995,0.790972312942024,27.6563745783924
39916.69140625,3.00799225,0.792809987336839,27.7206289278615
40697.439453125,3.008147,0.79513247696583,27.8018348589451
41258.3203125,3.0073817,0.796919883237109,27.8643315817171
41903.640625,3.0086341,0.798574895994774,27.9221991606564
42644.11328125,3.0077314,0.800528282923821,27.9904994029308
43229.908203125,3.00817655,0.802489211711966,28.0590633465722
43870.560546875,3.00884615,0.8040711322958,28.1143752550979
44586.328125,3.0092168,0.805873962034428,28.177411259945
45296.892578125,3.0087733,0.807694668117705,28.2410723118079
45917.654296875,3.0095496,0.80911892185655,28.2908713935857
46708.16796875,3.0098982,0.811059577854893,28.3587264984228
47349.296875,3.009356,0.812803328893455,28.4196968144565
47959.609375,3.0089668,0.814240330960057,28.46994164196
48735.53515625,3.0088353,0.815819848957543,28.52516954397
49356.0234375,3.0096426,0.817479205208852,28.5831889933165
50122.12890625,3.0086856,0.819064720252018,28.6386265822384
50727.416015625,3.0097779,0.820303639264973,28.6819454288452
51483.1015625,3.008953,0.82207799952126,28.7439859972469
52108.951171875,3.00969175,0.823327056351636,28.7876593129943
52894.533203125,3.0096505,0.825012974257444,28.846607491519
53479.6484375,3.0100508,0.826255555472686,28.8900543871569
54150.421875,3.00955105,0.82768726883145,28.9401142948059
54926.02734375,3.0092926,0.829059715444888,28.9881019386325
55471.724609375,3.01071725,0.830219395562225,29.0286501944834
56212.3125,3.00906835,0.831634797692902,29.0781397794721
56908.30078125,3.0115104,0.83295763923395,29.124392980208
57533.48828125,3.0104538,0.834293340938979,29.1710958370272
58174.203125,3.0097332,0.835419086765763,29.2104575792225
58819.64453125,3.01000595,0.836530880285572,29.2493314785165
59490.267578125,3.0094154,0.837782756400115,29.2931033706334
60215.623046875,3.0106626,0.839030600625889,29.3367342876185
60851.97265625,3.0103607,0.840283684113256,29.3805483955684
61492.794921875,3.0097473,0.841419486058788,29.4202617503073
62273.685546875,3.0100164,0.842592157790949,29.4612642584248
62931.84375,3.00937735,0.843927837588985,29.5079663492652
63635.658203125,3.0099977,0.845126345857626,29.5498722327841
64304.13671875,3.00918175,0.846101448342162,29.5839667252504
65028.228515625,3.0100291,0.847300419400403,29.6258887902239
65681.8671875,3.0097033,0.848509826827208,29.6681757631891
66450.94921875,3.010293,0.849599324484001,29.7062700868532
67114.6484375,3.00908545,0.850741773773366,29.7462158662016
67908.78515625,3.0100338,0.851972410065255,29.7892451071768
68506.73828125,3.00904105,0.852891802376226,29.8213916914764
69110.20703125,3.00923765,0.853910251898331,29.857001814627
69798.765625,3.00921965,0.854930447062703,29.8926729742204
70472.26171875,3.0106311,0.856002887956317,29.9301709075635
71181.08203125,3.0093507,0.85703680456009,29.9663218377654
71844.53125,3.0087583,0.857972918673196,29.9990531004614
72523.4296875,3.0085939,0.858977425608135,30.0341757205642
73171.484375,3.0087043,0.859972404034512,30.0689651760319
73830.27734375,3.0089811,0.860892971915358,30.1011528641734
74569.3671875,3.00959525,0.861883418819871,30.1357838748207
75152.14453125,3.00945795,0.862638856703743,30.1621977868442
75946.390625,3.0090525,0.863672268338863,30.1983310607994
76524.2890625,3.00912165,0.864696748279312,30.2341520377382
77223.34765625,3.0092883,0.865685586849367,30.2687268129149
77916.96875,3.00882055,0.866632768651605,30.3018450577484
78555.73828125,3.0095118,0.8673993419658,30.3286483204825
79269.953125,3.00871635,0.868350847922612,30.3619177595319
80018.44140625,3.0078259,0.869338180954692,30.3964398935207
80571.37109375,3.0082244,0.870096408142215,30.4229513336439
81254.7890625,3.00862025,0.871017848428244,30.4551695254631
81994.3203125,3.00868235,0.871930843257662,30.4870924215966
82562.515625,3.00860275,0.872709286568179,30.5143107191671
83246.19140625,3.00826695,0.873619914876171,30.5461508697962
83879.0078125,3.00970745,0.874271467693123,30.5689324368225
84533.0390625,3.00740325,0.875166176854685,30.60021597394
85261.9453125,3.007519,0.876112169744762,30.6332926484182
86010.5234375,3.0077116,0.876949307198039,30.6625631887426
86588.6640625,3.00796365,0.877669521562806,30.687745509189
87408.04296875,3.0085137,0.878662163635506,30.7224532739687
88106.8046875,3.0078547,0.879351817717743,30.7465670530679
88689.80078125,3.00832095,0.880173139645253,30.7752846029809
89423.6328125,3.0069168,0.881041601005758,30.8056503848167
90003.4609375,3.00736425,0.881696027886906,30.8285324435981